Workbook
Name Speciale_dagen: Basisgegevens!$D$4:$D$22

Sheet Jan
A1: =IF(Basisgegevens!D1="","NAAM",Basisgegevens!D1) -> NAAM | C1: Werkuren | H1: Speciale Dagen | J1: Halve/ hele dag | K1: Werkuren | M1: Reisuren | O1: 1 | P1: Overuren | Q1: Zon- en Feestdag | R1: KMs | S1: KMs | T1: Project | U1: Opmerkingen | V1: FD | W1: Week | X1: Kostprijs | Y1: Opbrengst | AE1: Dag > 5u gewerkt
C2: Vertrek | D2: Start | E2: Einde | F2: Aankomst | G2: Pauze | H2: Code | I2: Duur | K2: u:mm | L2: , getal | M2: u:mm | N2: , getal | R2: heen | S2: terug | AE2: MC teller
A3: =IF(WEEKDAY(B3)=1,"Zondag",IF(WEEKDAY(B3)=2,"Maandag",IF(WEEKDAY(B3)=3,"Dinsdag",IF(WEEKDAY(B3)=4,"Woensdag",IF(WEEKDAY(B3)=5,"Donderdag",IF(WEEKDAY(B3)=6,"Vrijdag","Zaterdag")))))) -> Donderdag | B3: =Basisgegevens!B1 -> 46023 | J3: =IF(I3="","",IF(HOUR(I3)<5,0.5,1)) | K3: =IF(Basisgegevens!$F$1="JA",IF(D3="",0,(1-D3)+(E3)-G3),(E3-D3)-G3) -> 0 | L3: =IF(D3="","",ROUNDDOWN((HOUR(K3))+MINUTE(K3)/60,2)) | M3: =IF(C3="",0,(D3-C3)+(F3-E3)) -> 0 | N3: =IF(C3="","",ROUNDDOWN((HOUR(M3))+MINUTE(M3)/60,2)) | O3: =IF(OR(WEEKDAY(B3)=1,WEEKDAY(B3)=7,B3=Basisgegevens!B$4,B3=Basisgegevens!B$5,B3=Basisgegevens!B$6,B3=Basisgegevens!B$7,B3=Basisgegevens!B$8,B3=Basisgegevens!B$9,B3=Basisgegevens!B$10,B3=Basisgegevens!B$11,B3=Basisgegevens!B$12,B3=Basisgegevens!B$13,B3=Basisgegevens!B$14,B3=Basisgegevens!B$15),0,IF(K3<=(TIME(8,0,0)),K3,(TIME(8,0,0)))) -> 0 | P3: =IF(OR(WEEKDAY(B3)=1,B3=Basisgegevens!B$4,B3=Basisgegevens!B$5,B3=Basisgegevens!B$6,B3=Basisgegevens!B$7,B3=Basisgegevens!B$8,B3=Basisgegevens!B$9,B3=Basisgegevens!B$10,B3=Basisgegevens!B$11,B3=Basisgegevens!B$12,B3=Basisgegevens!B$13,B3=Basisgegevens!B$14,B3=Basisgegevens!B$15),0,IF(WEEKDAY(B3)=7,K3,K3-O3)) -> 0 | Q3: =IF(OR(WEEKDAY(B3)=1,B3=Basisgegevens!B$4,B3=Basisgegevens!B$5,B3=Basisgegevens!B$6,B3=Basisgegevens!B$7,B3=Basisgegevens!B$8,B3=Basisgegevens!B$9,B3=Basisgegevens!B$10,B3=Basisgegevens!B$11,B3=Basisgegevens!B$12,B3=Basisgegevens!B$13,B3=Basisgegevens!B$14,B3=Basisgegevens!B$15),K3,0) -> 0 | V3: =IF(OR(B3=Basisgegevens!$B$4,B3=Basisgegevens!$B$5,B3=Basisgegevens!$B$6,B3=Basisgegevens!$B$7,B3=Basisgegevens!$B$8,B3=Basisgegevens!$B$9,B3=Basisgegevens!$B$10,B3=Basisgegevens!$B$11,B3=Basisgegevens!$B$12,B3=Basisgegevens!$B$13,B3=Basisgegevens!$B$14,B3=Basisgegevens!$B$15),"FD","") -> FD | W3: =IF(WEEKDAY(B3)=1,(WEEKNUM(DATE(YEAR(B3),MONTH(B3),DAY(B3)),)-1),WEEKNUM(DATE(YEAR(B3),MONTH(B3),DAY(B3)),)) -> 1 | X3: =IF($D3="","",IF($B3<Basisgegevens!$H$4,((((DAY($O3))*24)+(HOUR($O3))+((MINUTE($O3))/60))*Basisgegevens!$I$3)+((((DAY($P3))*24)+(HOUR($P3))+((MINUTE($P3))/60))*Basisgegevens!$I$3*1.5)+((((DAY($Q3))*24)+(HOUR($Q3))+((MINUTE($Q3))/60))*Basisgegevens!$I$3*2)+Basisgegevens!$J$3,IF(Jan!$B3<Basisgegevens!$H$5,((((DAY($O3))*24)+(HOUR($O3))+((MINUTE($O3))/60))*Basisgegevens!$I$4)+((((DAY($P3))*24)+(HOUR($P3))+((MINUTE($P3))/60))*Basisgegevens!$I$4*1.5)+((((DAY($Q3))*24)+(HOUR($Q3))+((MINUTE($Q3))/60))*Basisgegevens!$I$4*2)+Basisgegevens!$J$4,((((DAY($O3))*24)+(HOUR($O3))+((MINUTE($O3))/60))*Basisgegevens!$I$5)+((((DAY($P3))*24)+(HOUR($P3))+((MINUTE($P3))/60))*Basisgegevens!$I$5*1.5)+((((DAY($Q3))*24)+(HOUR($Q3))+((MINUTE($Q3))/60))*Basisgegevens!$I$5*2)+Basisgegevens!$J$5))) | Y3: =IF($D3="","",IF($B3<Basisgegevens!$H$4,((((DAY($O3))*24)+(HOUR($O3))+((MINUTE($O3))/60))*Basisgegevens!$K$3)+((((DAY($P3))*24)+(HOUR($P3))+((MINUTE($P3))/60))*Basisgegevens!$K$3*1.5)+((((DAY($Q3))*24)+(HOUR($Q3))+((MINUTE($Q3))/60))*Basisgegevens!$K$3*2)+Basisgegevens!$L$3,IF(Jan!$B3<Basisgegevens!$H$5,((((DAY($O3))*24)+(HOUR($O3))+((MINUTE($O3))/60))*Basisgegevens!$K$4)+((((DAY($P3))*24)+(HOUR($P3))+((MINUTE($P3))/60))*Basisgegevens!$K$4*1.5)+((((DAY($Q3))*24)+(HOUR($Q3))+((MINUTE($Q3))/60))*Basisgegevens!$K$4*2)+Basisgegevens!$L$4,((((DAY($O3))*24)+(HOUR($O3))+((MINUTE($O3))/60))*Basisgegevens!$K$5)+((((DAY($P3))*24)+(HOUR($P3))+((MINUTE($P3))/60))*Basisgegevens!$K$5*1.5)+((((DAY($Q3))*24)+(HOUR($Q3))+((MINUTE($Q3))/60))*Basisgegevens!$K$5*2)+Basisgegevens!$L$5))) | Z3: WEEK | AA3: Werkuren | AB3: Totale uren | AC3: Reisuren | AD3: ADV teller | AE3: =IF(L3="",0,IF(L3>=5,1,0)) -> 0
A4: =IF(WEEKDAY(B4)=1,"Zondag",IF(WEEKDAY(B4)=2,"Maandag",IF(WEEKDAY(B4)=3,"Dinsdag",IF(WEEKDAY(B4)=4,"Woensdag",IF(WEEKDAY(B4)=5,"Donderdag",IF(WEEKDAY(B4)=6,"Vrijdag","Zaterdag")))))) -> Vrijdag | B4: =B3+1 -> 46024 | J4: =IF(I4="","",IF(HOUR(I4)<5,0.5,1)) | K4: =IF(Basisgegevens!$F$1="JA",IF(D4="",0,(1-D4)+(E4)-G4),(E4-D4)-G4) -> 0 | L4: =IF(D4="","",ROUNDDOWN((HOUR(K4))+MINUTE(K4)/60,2)) | M4: =IF(C4="",0,(D4-C4)+(F4-E4)) -> 0 | N4: =IF(C4="","",ROUNDDOWN((HOUR(M4))+MINUTE(M4)/60,2)) | O4: =IF(OR(WEEKDAY(B4)=1,WEEKDAY(B4)=7,B4=Basisgegevens!B$4,B4=Basisgegevens!B$5,B4=Basisgegevens!B$6,B4=Basisgegevens!B$7,B4=Basisgegevens!B$8,B4=Basisgegevens!B$9,B4=Basisgegevens!B$10,B4=Basisgegevens!B$11,B4=Basisgegevens!B$12,B4=Basisgegevens!B$13,B4=Basisgegevens!B$14,B4=Basisgegevens!B$15),0,IF(K4<=(TIME(8,0,0)),K4,(TIME(8,0,0)))) -> 0 | P4: =IF(OR(WEEKDAY(B4)=1,B4=Basisgegevens!B$4,B4=Basisgegevens!B$5,B4=Basisgegevens!B$6,B4=Basisgegevens!B$7,B4=Basisgegevens!B$8,B4=Basisgegevens!B$9,B4=Basisgegevens!B$10,B4=Basisgegevens!B$11,B4=Basisgegevens!B$12,B4=Basisgegevens!B$13,B4=Basisgegevens!B$14,B4=Basisgegevens!B$15),0,IF(WEEKDAY(B4)=7,K4,K4-O4)) -> 0 | Q4: =IF(OR(WEEKDAY(B4)=1,B4=Basisgegevens!B$4,B4=Basisgegevens!B$5,B4=Basisgegevens!B$6,B4=Basisgegevens!B$7,B4=Basisgegevens!B$8,B4=Basisgegevens!B$9,B4=Basisgegevens!B$10,B4=Basisgegevens!B$11,B4=Basisgegevens!B$12,B4=Basisgegevens!B$13,B4=Basisgegevens!B$14,B4=Basisgegevens!B$15),K4,0) -> 0 | V4: =IF(OR(B4=Basisgegevens!$B$4,B4=Basisgegevens!$B$5,B4=Basisgegevens!$B$6,B4=Basisgegevens!$B$7,B4=Basisgegevens!$B$8,B4=Basisgegevens!$B$9,B4=Basisgegevens!$B$10,B4=Basisgegevens!$B$11,B4=Basisgegevens!$B$12,B4=Basisgegevens!$B$13,B4=Basisgegevens!$B$14,B4=Basisgegevens!$B$15),"FD","") | W4: =IF(WEEKDAY(B4)=1,(WEEKNUM(DATE(YEAR(B4),MONTH(B4),DAY(B4)),)-1),WEEKNUM(DATE(YEAR(B4),MONTH(B4),DAY(B4)),)) -> 1 | X4: =IF($D4="","",IF($B4<Basisgegevens!$H$4,((((DAY($O4))*24)+(HOUR($O4))+((MINUTE($O4))/60))*Basisgegevens!$I$3)+((((DAY($P4))*24)+(HOUR($P4))+((MINUTE($P4))/60))*Basisgegevens!$I$3*1.5)+((((DAY($Q4))*24)+(HOUR($Q4))+((MINUTE($Q4))/60))*Basisgegevens!$I$3*2)+Basisgegevens!$J$3,IF(Jan!$B4<Basisgegevens!$H$5,((((DAY($O4))*24)+(HOUR($O4))+((MINUTE($O4))/60))*Basisgegevens!$I$4)+((((DAY($P4))*24)+(HOUR($P4))+((MINUTE($P4))/60))*Basisgegevens!$I$4*1.5)+((((DAY($Q4))*24)+(HOUR($Q4))+((MINUTE($Q4))/60))*Basisgegevens!$I$4*2)+Basisgegevens!$J$4,((((DAY($O4))*24)+(HOUR($O4))+((MINUTE($O4))/60))*Basisgegevens!$I$5)+((((DAY($P4))*24)+(HOUR($P4))+((MINUTE($P4))/60))*Basisgegevens!$I$5*1.5)+((((DAY($Q4))*24)+(HOUR($Q4))+((MINUTE($Q4))/60))*Basisgegevens!$I$5*2)+Basisgegevens!$J$5))) | Y4: =IF($D4="","",IF($B4<Basisgegevens!$H$4,((((DAY($O4))*24)+(HOUR($O4))+((MINUTE($O4))/60))*Basisgegevens!$K$3)+((((DAY($P4))*24)+(HOUR($P4))+((MINUTE($P4))/60))*Basisgegevens!$K$3*1.5)+((((DAY($Q4))*24)+(HOUR($Q4))+((MINUTE($Q4))/60))*Basisgegevens!$K$3*2)+Basisgegevens!$L$3,IF(Jan!$B4<Basisgegevens!$H$5,((((DAY($O4))*24)+(HOUR($O4))+((MINUTE($O4))/60))*Basisgegevens!$K$4)+((((DAY($P4))*24)+(HOUR($P4))+((MINUTE($P4))/60))*Basisgegevens!$K$4*1.5)+((((DAY($Q4))*24)+(HOUR($Q4))+((MINUTE($Q4))/60))*Basisgegevens!$K$4*2)+Basisgegevens!$L$4,((((DAY($O4))*24)+(HOUR($O4))+((MINUTE($O4))/60))*Basisgegevens!$K$5)+((((DAY($P4))*24)+(HOUR($P4))+((MINUTE($P4))/60))*Basisgegevens!$K$5*1.5)+((((DAY($Q4))*24)+(HOUR($Q4))+((MINUTE($Q4))/60))*Basisgegevens!$K$5*2)+Basisgegevens!$L$5))) | Z4: =LOOKUP(SMALL(W3:W33,1),W3:W33,W3:W33) -> 1 | AA4: =IF($Z4="","",SUMIFS($K$3:$K$33,$W$3:$W$33,$Z4,$A$3:$A$33,"<>Zaterdag",$A$3:$A$33,"<>Zondag")) -> 0 | AB4: =IF($Z4="","",SUMIFS($K$3:$K$33,$W$3:$W$33,$Z4,$A$3:$A$33,"<>Zaterdag",$A$3:$A$33,"<>Zondag")+SUMIFS($I$3:$I$33,$W$3:$W$33,$Z4,$A$3:$A$33,"<>Zaterdag",$A$3:$A$33,"<>Zondag")) -> 0 | AC4: =IF($Z4="","",SUMIFS($M$3:$M$33,$W$3:$W$33,$Z4,$A$3:$A$33,"<>Zaterdag",$A$3:$A$33,"<>Zondag")) -> 0 | AD4: =IF($Z4="","",SUMIFS($K$3:$K$33,$W$3:$W$33,$Z4,$A$3:$A$33,"<>Zaterdag",$A$3:$A$33,"<>Zondag")+SUMIFS($I$3:$I$33,$W$3:$W$33,$Z4,$A$3:$A$33,"<>Zaterdag",$A$3:$A$33,"<>Zondag",$H$3:$H$33,"=ADV")+SUMIFS($I$3:$I$33,$W$3:$W$33,$Z4,$A$3:$A$33,"<>Zaterdag",$A$3:$A$33,"<>Zondag",$H$3:$H$33,"=BF")+SUMIFS($I$3:$I$33,$W$3:$W$33,$Z4,$A$3:$A$33,"<>Zaterdag",$A$3:$A$33,"<>Zondag",$H$3:$H$33,"=BIR")+SUMIFS($I$3:$I$33,$W$3:$W$33,$Z4,$A$3:$A$33,"<>Zaterdag",$A$3:$A$33,"<>Zondag",$H$3:$H$33,"=OPL")) -> 0 | AE4: =IF(L4="",0,IF(L4>=5,1,0)) -> 0
A5: =IF(WEEKDAY(B5)=1,"Zondag",IF(WEEKDAY(B5)=2,"Maandag",IF(WEEKDAY(B5)=3,"Dinsdag",IF(WEEKDAY(B5)=4,"Woensdag",IF(WEEKDAY(B5)=5,"Donderdag",IF(WEEKDAY(B5)=6,"Vrijdag","Zaterdag")))))) -> Zaterdag | B5: =B4+1 -> 46025 | J5: =IF(I5="","",IF(HOUR(I5)<5,0.5,1)) | K5: =IF(Basisgegevens!$F$1="JA",IF(D5="",0,(1-D5)+(E5)-G5),(E5-D5)-G5) -> 0 | L5: =IF(D5="","",ROUNDDOWN((HOUR(K5))+MINUTE(K5)/60,2)) | M5: =IF(C5="",0,(D5-C5)+(F5-E5)) -> 0 | N5: =IF(C5="","",ROUNDDOWN((HOUR(M5))+MINUTE(M5)/60,2)) | O5: =IF(OR(WEEKDAY(B5)=1,WEEKDAY(B5)=7,B5=Basisgegevens!B$4,B5=Basisgegevens!B$5,B5=Basisgegevens!B$6,B5=Basisgegevens!B$7,B5=Basisgegevens!B$8,B5=Basisgegevens!B$9,B5=Basisgegevens!B$10,B5=Basisgegevens!B$11,B5=Basisgegevens!B$12,B5=Basisgegevens!B$13,B5=Basisgegevens!B$14,B5=Basisgegevens!B$15),0,IF(K5<=(TIME(8,0,0)),K5,(TIME(8,0,0)))) -> 0 | P5: =IF(OR(WEEKDAY(B5)=1,B5=Basisgegevens!B$4,B5=Basisgegevens!B$5,B5=Basisgegevens!B$6,B5=Basisgegevens!B$7,B5=Basisgegevens!B$8,B5=Basisgegevens!B$9,B5=Basisgegevens!B$10,B5=Basisgegevens!B$11,B5=Basisgegevens!B$12,B5=Basisgegevens!B$13,B5=Basisgegevens!B$14,B5=Basisgegevens!B$15),0,IF(WEEKDAY(B5)=7,K5,K5-O5)) -> 0 | Q5: =IF(OR(WEEKDAY(B5)=1,B5=Basisgegevens!B$4,B5=Basisgegevens!B$5,B5=Basisgegevens!B$6,B5=Basisgegevens!B$7,B5=Basisgegevens!B$8,B5=Basisgegevens!B$9,B5=Basisgegevens!B$10,B5=Basisgegevens!B$11,B5=Basisgegevens!B$12,B5=Basisgegevens!B$13,B5=Basisgegevens!B$14,B5=Basisgegevens!B$15),K5,0) -> 0 | V5: =IF(OR(B5=Basisgegevens!$B$4,B5=Basisgegevens!$B$5,B5=Basisgegevens!$B$6,B5=Basisgegevens!$B$7,B5=Basisgegevens!$B$8,B5=Basisgegevens!$B$9,B5=Basisgegevens!$B$10,B5=Basisgegevens!$B$11,B5=Basisgegevens!$B$12,B5=Basisgegevens!$B$13,B5=Basisgegevens!$B$14,B5=Basisgegevens!$B$15),"FD","") | W5: =IF(WEEKDAY(B5)=1,(WEEKNUM(DATE(YEAR(B5),MONTH(B5),DAY(B5)),)-1),WEEKNUM(DATE(YEAR(B5),MONTH(B5),DAY(B5)),)) -> 1 | X5: =IF($D5="","",IF($B5<Basisgegevens!$H$4,((((DAY($O5))*24)+(HOUR($O5))+((MINUTE($O5))/60))*Basisgegevens!$I$3)+((((DAY($P5))*24)+(HOUR($P5))+((MINUTE($P5))/60))*Basisgegevens!$I$3*1.5)+((((DAY($Q5))*24)+(HOUR($Q5))+((MINUTE($Q5))/60))*Basisgegevens!$I$3*2)+Basisgegevens!$J$3,IF(Jan!$B5<Basisgegevens!$H$5,((((DAY($O5))*24)+(HOUR($O5))+((MINUTE($O5))/60))*Basisgegevens!$I$4)+((((DAY($P5))*24)+(HOUR($P5))+((MINUTE($P5))/60))*Basisgegevens!$I$4*1.5)+((((DAY($Q5))*24)+(HOUR($Q5))+((MINUTE($Q5))/60))*Basisgegevens!$I$4*2)+Basisgegevens!$J$4,((((DAY($O5))*24)+(HOUR($O5))+((MINUTE($O5))/60))*Basisgegevens!$I$5)+((((DAY($P5))*24)+(HOUR($P5))+((MINUTE($P5))/60))*Basisgegevens!$I$5*1.5)+((((DAY($Q5))*24)+(HOUR($Q5))+((MINUTE($Q5))/60))*Basisgegevens!$I$5*2)+Basisgegevens!$J$5))) | Y5: =IF($D5="","",IF($B5<Basisgegevens!$H$4,((((DAY($O5))*24)+(HOUR($O5))+((MINUTE($O5))/60))*Basisgegevens!$K$3)+((((DAY($P5))*24)+(HOUR($P5))+((MINUTE($P5))/60))*Basisgegevens!$K$3*1.5)+((((DAY($Q5))*24)+(HOUR($Q5))+((MINUTE($Q5))/60))*Basisgegevens!$K$3*2)+Basisgegevens!$L$3,IF(Jan!$B5<Basisgegevens!$H$5,((((DAY($O5))*24)+(HOUR($O5))+((MINUTE($O5))/60))*Basisgegevens!$K$4)+((((DAY($P5))*24)+(HOUR($P5))+((MINUTE($P5))/60))*Basisgegevens!$K$4*1.5)+((((DAY($Q5))*24)+(HOUR($Q5))+((MINUTE($Q5))/60))*Basisgegevens!$K$4*2)+Basisgegevens!$L$4,((((DAY($O5))*24)+(HOUR($O5))+((MINUTE($O5))/60))*Basisgegevens!$K$5)+((((DAY($P5))*24)+(HOUR($P5))+((MINUTE($P5))/60))*Basisgegevens!$K$5*1.5)+((((DAY($Q5))*24)+(HOUR($Q5))+((MINUTE($Q5))/60))*Basisgegevens!$K$5*2)+Basisgegevens!$L$5))) | Z5: =IF(W$33=Z4,"",Z4+1) -> 2 | AA5: =IF($Z5="","",SUMIFS($K$3:$K$33,$W$3:$W$33,$Z5,$A$3:$A$33,"<>Zaterdag",$A$3:$A$33,"<>Zondag")) -> 0 | AB5: =IF($Z5="","",SUMIFS($K$3:$K$33,$W$3:$W$33,$Z5,$A$3:$A$33,"<>Zaterdag",$A$3:$A$33,"<>Zondag")+SUMIFS($I$3:$I$33,$W$3:$W$33,$Z5,$A$3:$A$33,"<>Zaterdag",$A$3:$A$33,"<>Zondag")) -> 0 | AC5: =IF($Z5="","",SUMIFS($M$3:$M$33,$W$3:$W$33,$Z5,$A$3:$A$33,"<>Zaterdag",$A$3:$A$33,"<>Zondag")) -> 0 | AD5: =IF($Z5="","",SUMIFS($K$3:$K$33,$W$3:$W$33,$Z5,$A$3:$A$33,"<>Zaterdag",$A$3:$A$33,"<>Zondag")+SUMIFS($I$3:$I$33,$W$3:$W$33,$Z5,$A$3:$A$33,"<>Zaterdag",$A$3:$A$33,"<>Zondag",$H$3:$H$33,"=ADV")+SUMIFS($I$3:$I$33,$W$3:$W$33,$Z5,$A$3:$A$33,"<>Zaterdag",$A$3:$A$33,"<>Zondag",$H$3:$H$33,"=BF")+SUMIFS($I$3:$I$33,$W$3:$W$33,$Z5,$A$3:$A$33,"<>Zaterdag",$A$3:$A$33,"<>Zondag",$H$3:$H$33,"=BIR")+SUMIFS($I$3:$I$33,$W$3:$W$33,$Z5,$A$3:$A$33,"<>Zaterdag",$A$3:$A$33,"<>Zondag",$H$3:$H$33,"=OPL")) -> 0 | AE5: =IF(L5="",0,IF(L5>=5,1,0)) -> 0
A6: =IF(WEEKDAY(B6)=1,"Zondag",IF(WEEKDAY(B6)=2,"Maandag",IF(WEEKDAY(B6)=3,"Dinsdag",IF(WEEKDAY(B6)=4,"Woensdag",IF(WEEKDAY(B6)=5,"Donderdag",IF(WEEKDAY(B6)=6,"Vrijdag","Zaterdag")))))) -> Zondag | B6: =B5+1 -> 46026 | J6: =IF(I6="","",IF(HOUR(I6)<5,0.5,1)) | K6: =IF(Basisgegevens!$F$1="JA",IF(D6="",0,(1-D6)+(E6)-G6),(E6-D6)-G6) -> 0 | L6: =IF(D6="","",ROUNDDOWN((HOUR(K6))+MINUTE(K6)/60,2)) | M6: =IF(C6="",0,(D6-C6)+(F6-E6)) -> 0 | N6: =IF(C6="","",ROUNDDOWN((HOUR(M6))+MINUTE(M6)/60,2)) | O6: =IF(OR(WEEKDAY(B6)=1,WEEKDAY(B6)=7,B6=Basisgegevens!B$4,B6=Basisgegevens!B$5,B6=Basisgegevens!B$6,B6=Basisgegevens!B$7,B6=Basisgegevens!B$8,B6=Basisgegevens!B$9,B6=Basisgegevens!B$10,B6=Basisgegevens!B$11,B6=Basisgegevens!B$12,B6=Basisgegevens!B$13,B6=Basisgegevens!B$14,B6=Basisgegevens!B$15),0,IF(K6<=(TIME(8,0,0)),K6,(TIME(8,0,0)))) -> 0 | P6: =IF(OR(WEEKDAY(B6)=1,B6=Basisgegevens!B$4,B6=Basisgegevens!B$5,B6=Basisgegevens!B$6,B6=Basisgegevens!B$7,B6=Basisgegevens!B$8,B6=Basisgegevens!B$9,B6=Basisgegevens!B$10,B6=Basisgegevens!B$11,B6=Basisgegevens!B$12,B6=Basisgegevens!B$13,B6=Basisgegevens!B$14,B6=Basisgegevens!B$15),0,IF(WEEKDAY(B6)=7,K6,K6-O6)) -> 0 | Q6: =IF(OR(WEEKDAY(B6)=1,B6=Basisgegevens!B$4,B6=Basisgegevens!B$5,B6=Basisgegevens!B$6,B6=Basisgegevens!B$7,B6=Basisgegevens!B$8,B6=Basisgegevens!B$9,B6=Basisgegevens!B$10,B6=Basisgegevens!B$11,B6=Basisgegevens!B$12,B6=Basisgegevens!B$13,B6=Basisgegevens!B$14,B6=Basisgegevens!B$15),K6,0) -> 0 | V6: =IF(OR(B6=Basisgegevens!$B$4,B6=Basisgegevens!$B$5,B6=Basisgegevens!$B$6,B6=Basisgegevens!$B$7,B6=Basisgegevens!$B$8,B6=Basisgegevens!$B$9,B6=Basisgegevens!$B$10,B6=Basisgegevens!$B$11,B6=Basisgegevens!$B$12,B6=Basisgegevens!$B$13,B6=Basisgegevens!$B$14,B6=Basisgegevens!$B$15),"FD","") | W6: =IF(WEEKDAY(B6)=1,(WEEKNUM(DATE(YEAR(B6),MONTH(B6),DAY(B6)),)-1),WEEKNUM(DATE(YEAR(B6),MONTH(B6),DAY(B6)),)) -> 1 | X6: =IF($D6="","",IF($B6<Basisgegevens!$H$4,((((DAY($O6))*24)+(HOUR($O6))+((MINUTE($O6))/60))*Basisgegevens!$I$3)+((((DAY($P6))*24)+(HOUR($P6))+((MINUTE($P6))/60))*Basisgegevens!$I$3*1.5)+((((DAY($Q6))*24)+(HOUR($Q6))+((MINUTE($Q6))/60))*Basisgegevens!$I$3*2)+Basisgegevens!$J$3,IF(Jan!$B6<Basisgegevens!$H$5,((((DAY($O6))*24)+(HOUR($O6))+((MINUTE($O6))/60))*Basisgegevens!$I$4)+((((DAY($P6))*24)+(HOUR($P6))+((MINUTE($P6))/60))*Basisgegevens!$I$4*1.5)+((((DAY($Q6))*24)+(HOUR($Q6))+((MINUTE($Q6))/60))*Basisgegevens!$I$4*2)+Basisgegevens!$J$4,((((DAY($O6))*24)+(HOUR($O6))+((MINUTE($O6))/60))*Basisgegevens!$I$5)+((((DAY($P6))*24)+(HOUR($P6))+((MINUTE($P6))/60))*Basisgegevens!$I$5*1.5)+((((DAY($Q6))*24)+(HOUR($Q6))+((MINUTE($Q6))/60))*Basisgegevens!$I$5*2)+Basisgegevens!$J$5))) | Y6: =IF($D6="","",IF($B6<Basisgegevens!$H$4,((((DAY($O6))*24)+(HOUR($O6))+((MINUTE($O6))/60))*Basisgegevens!$K$3)+((((DAY($P6))*24)+(HOUR($P6))+((MINUTE($P6))/60))*Basisgegevens!$K$3*1.5)+((((DAY($Q6))*24)+(HOUR($Q6))+((MINUTE($Q6))/60))*Basisgegevens!$K$3*2)+Basisgegevens!$L$3,IF(Jan!$B6<Basisgegevens!$H$5,((((DAY($O6))*24)+(HOUR($O6))+((MINUTE($O6))/60))*Basisgegevens!$K$4)+((((DAY($P6))*24)+(HOUR($P6))+((MINUTE($P6))/60))*Basisgegevens!$K$4*1.5)+((((DAY($Q6))*24)+(HOUR($Q6))+((MINUTE($Q6))/60))*Basisgegevens!$K$4*2)+Basisgegevens!$L$4,((((DAY($O6))*24)+(HOUR($O6))+((MINUTE($O6))/60))*Basisgegevens!$K$5)+((((DAY($P6))*24)+(HOUR($P6))+((MINUTE($P6))/60))*Basisgegevens!$K$5*1.5)+((((DAY($Q6))*24)+(HOUR($Q6))+((MINUTE($Q6))/60))*Basisgegevens!$K$5*2)+Basisgegevens!$L$5))) | Z6: =IF(W$33=Z5,"",Z5+1) -> 3 | AA6: =IF($Z6="","",SUMIFS($K$3:$K$33,$W$3:$W$33,$Z6,$A$3:$A$33,"<>Zaterdag",$A$3:$A$33,"<>Zondag")) -> 0 | AB6: =IF($Z6="","",SUMIFS($K$3:$K$33,$W$3:$W$33,$Z6,$A$3:$A$33,"<>Zaterdag",$A$3:$A$33,"<>Zondag")+SUMIFS($I$3:$I$33,$W$3:$W$33,$Z6,$A$3:$A$33,"<>Zaterdag",$A$3:$A$33,"<>Zondag")) -> 0 | AC6: =IF($Z6="","",SUMIFS($M$3:$M$33,$W$3:$W$33,$Z6,$A$3:$A$33,"<>Zaterdag",$A$3:$A$33,"<>Zondag")) -> 0 | AD6: =IF($Z6="","",SUMIFS($K$3:$K$33,$W$3:$W$33,$Z6,$A$3:$A$33,"<>Zaterdag",$A$3:$A$33,"<>Zondag")+SUMIFS($I$3:$I$33,$W$3:$W$33,$Z6,$A$3:$A$33,"<>Zaterdag",$A$3:$A$33,"<>Zondag",$H$3:$H$33,"=ADV")+SUMIFS($I$3:$I$33,$W$3:$W$33,$Z6,$A$3:$A$33,"<>Zaterdag",$A$3:$A$33,"<>Zondag",$H$3:$H$33,"=BF")+SUMIFS($I$3:$I$33,$W$3:$W$33,$Z6,$A$3:$A$33,"<>Zaterdag",$A$3:$A$33,"<>Zondag",$H$3:$H$33,"=BIR")+SUMIFS($I$3:$I$33,$W$3:$W$33,$Z6,$A$3:$A$33,"<>Zaterdag",$A$3:$A$33,"<>Zondag",$H$3:$H$33,"=OPL")) -> 0 | AE6: =IF(L6="",0,IF(L6>=5,1,0)) -> 0
A7: =IF(WEEKDAY(B7)=1,"Zondag",IF(WEEKDAY(B7)=2,"Maandag",IF(WEEKDAY(B7)=3,"Dinsdag",IF(WEEKDAY(B7)=4,"Woensdag",IF(WEEKDAY(B7)=5,"Donderdag",IF(WEEKDAY(B7)=6,"Vrijdag","Zaterdag")))))) -> Maandag | B7: =B6+1 -> 46027 | J7: =IF(I7="","",IF(HOUR(I7)<5,0.5,1)) | K7: =IF(Basisgegevens!$F$1="JA",IF(D7="",0,(1-D7)+(E7)-G7),(E7-D7)-G7) -> 0 | L7: =IF(D7="","",ROUNDDOWN((HOUR(K7))+MINUTE(K7)/60,2)) | M7: =IF(C7="",0,(D7-C7)+(F7-E7)) -> 0 | N7: =IF(C7="","",ROUNDDOWN((HOUR(M7))+MINUTE(M7)/60,2)) | O7: =IF(OR(WEEKDAY(B7)=1,WEEKDAY(B7)=7,B7=Basisgegevens!B$4,B7=Basisgegevens!B$5,B7=Basisgegevens!B$6,B7=Basisgegevens!B$7,B7=Basisgegevens!B$8,B7=Basisgegevens!B$9,B7=Basisgegevens!B$10,B7=Basisgegevens!B$11,B7=Basisgegevens!B$12,B7=Basisgegevens!B$13,B7=Basisgegevens!B$14,B7=Basisgegevens!B$15),0,IF(K7<=(TIME(8,0,0)),K7,(TIME(8,0,0)))) -> 0 | P7: =IF(OR(WEEKDAY(B7)=1,B7=Basisgegevens!B$4,B7=Basisgegevens!B$5,B7=Basisgegevens!B$6,B7=Basisgegevens!B$7,B7=Basisgegevens!B$8,B7=Basisgegevens!B$9,B7=Basisgegevens!B$10,B7=Basisgegevens!B$11,B7=Basisgegevens!B$12,B7=Basisgegevens!B$13,B7=Basisgegevens!B$14,B7=Basisgegevens!B$15),0,IF(WEEKDAY(B7)=7,K7,K7-O7)) -> 0 | Q7: =IF(OR(WEEKDAY(B7)=1,B7=Basisgegevens!B$4,B7=Basisgegevens!B$5,B7=Basisgegevens!B$6,B7=Basisgegevens!B$7,B7=Basisgegevens!B$8,B7=Basisgegevens!B$9,B7=Basisgegevens!B$10,B7=Basisgegevens!B$11,B7=Basisgegevens!B$12,B7=Basisgegevens!B$13,B7=Basisgegevens!B$14,B7=Basisgegevens!B$15),K7,0) -> 0 | V7: =IF(OR(B7=Basisgegevens!$B$4,B7=Basisgegevens!$B$5,B7=Basisgegevens!$B$6,B7=Basisgegevens!$B$7,B7=Basisgegevens!$B$8,B7=Basisgegevens!$B$9,B7=Basisgegevens!$B$10,B7=Basisgegevens!$B$11,B7=Basisgegevens!$B$12,B7=Basisgegevens!$B$13,B7=Basisgegevens!$B$14,B7=Basisgegevens!$B$15),"FD","") | W7: =IF(WEEKDAY(B7)=1,(WEEKNUM(DATE(YEAR(B7),MONTH(B7),DAY(B7)),)-1),WEEKNUM(DATE(YEAR(B7),MONTH(B7),DAY(B7)),)) -> 2 | X7: =IF($D7="","",IF($B7<Basisgegevens!$H$4,((((DAY($O7))*24)+(HOUR($O7))+((MINUTE($O7))/60))*Basisgegevens!$I$3)+((((DAY($P7))*24)+(HOUR($P7))+((MINUTE($P7))/60))*Basisgegevens!$I$3*1.5)+((((DAY($Q7))*24)+(HOUR($Q7))+((MINUTE($Q7))/60))*Basisgegevens!$I$3*2)+Basisgegevens!$J$3,IF(Jan!$B7<Basisgegevens!$H$5,((((DAY($O7))*24)+(HOUR($O7))+((MINUTE($O7))/60))*Basisgegevens!$I$4)+((((DAY($P7))*24)+(HOUR($P7))+((MINUTE($P7))/60))*Basisgegevens!$I$4*1.5)+((((DAY($Q7))*24)+(HOUR($Q7))+((MINUTE($Q7))/60))*Basisgegevens!$I$4*2)+Basisgegevens!$J$4,((((DAY($O7))*24)+(HOUR($O7))+((MINUTE($O7))/60))*Basisgegevens!$I$5)+((((DAY($P7))*24)+(HOUR($P7))+((MINUTE($P7))/60))*Basisgegevens!$I$5*1.5)+((((DAY($Q7))*24)+(HOUR($Q7))+((MINUTE($Q7))/60))*Basisgegevens!$I$5*2)+Basisgegevens!$J$5))) | Y7: =IF($D7="","",IF($B7<Basisgegevens!$H$4,((((DAY($O7))*24)+(HOUR($O7))+((MINUTE($O7))/60))*Basisgegevens!$K$3)+((((DAY($P7))*24)+(HOUR($P7))+((MINUTE($P7))/60))*Basisgegevens!$K$3*1.5)+((((DAY($Q7))*24)+(HOUR($Q7))+((MINUTE($Q7))/60))*Basisgegevens!$K$3*2)+Basisgegevens!$L$3,IF(Jan!$B7<Basisgegevens!$H$5,((((DAY($O7))*24)+(HOUR($O7))+((MINUTE($O7))/60))*Basisgegevens!$K$4)+((((DAY($P7))*24)+(HOUR($P7))+((MINUTE($P7))/60))*Basisgegevens!$K$4*1.5)+((((DAY($Q7))*24)+(HOUR($Q7))+((MINUTE($Q7))/60))*Basisgegevens!$K$4*2)+Basisgegevens!$L$4,((((DAY($O7))*24)+(HOUR($O7))+((MINUTE($O7))/60))*Basisgegevens!$K$5)+((((DAY($P7))*24)+(HOUR($P7))+((MINUTE($P7))/60))*Basisgegevens!$K$5*1.5)+((((DAY($Q7))*24)+(HOUR($Q7))+((MINUTE($Q7))/60))*Basisgegevens!$K$5*2)+Basisgegevens!$L$5))) | Z7: =IF(W$33=Z6,"",Z6+1) -> 4 | AA7: =IF($Z7="","",SUMIFS($K$3:$K$33,$W$3:$W$33,$Z7,$A$3:$A$33,"<>Zaterdag",$A$3:$A$33,"<>Zondag")) -> 0 | AB7: =IF($Z7="","",SUMIFS($K$3:$K$33,$W$3:$W$33,$Z7,$A$3:$A$33,"<>Zaterdag",$A$3:$A$33,"<>Zondag")+SUMIFS($I$3:$I$33,$W$3:$W$33,$Z7,$A$3:$A$33,"<>Zaterdag",$A$3:$A$33,"<>Zondag")) -> 0 | AC7: =IF($Z7="","",SUMIFS($M$3:$M$33,$W$3:$W$33,$Z7,$A$3:$A$33,"<>Zaterdag",$A$3:$A$33,"<>Zondag")) -> 0 | AD7: =IF($Z7="","",SUMIFS($K$3:$K$33,$W$3:$W$33,$Z7,$A$3:$A$33,"<>Zaterdag",$A$3:$A$33,"<>Zondag")+SUMIFS($I$3:$I$33,$W$3:$W$33,$Z7,$A$3:$A$33,"<>Zaterdag",$A$3:$A$33,"<>Zondag",$H$3:$H$33,"=ADV")+SUMIFS($I$3:$I$33,$W$3:$W$33,$Z7,$A$3:$A$33,"<>Zaterdag",$A$3:$A$33,"<>Zondag",$H$3:$H$33,"=BF")+SUMIFS($I$3:$I$33,$W$3:$W$33,$Z7,$A$3:$A$33,"<>Zaterdag",$A$3:$A$33,"<>Zondag",$H$3:$H$33,"=BIR")+SUMIFS($I$3:$I$33,$W$3:$W$33,$Z7,$A$3:$A$33,"<>Zaterdag",$A$3:$A$33,"<>Zondag",$H$3:$H$33,"=OPL")) -> 0 | AE7: =IF(L7="",0,IF(L7>=5,1,0)) -> 0
A8: =IF(WEEKDAY(B8)=1,"Zondag",IF(WEEKDAY(B8)=2,"Maandag",IF(WEEKDAY(B8)=3,"Dinsdag",IF(WEEKDAY(B8)=4,"Woensdag",IF(WEEKDAY(B8)=5,"Donderdag",IF(WEEKDAY(B8)=6,"Vrijdag","Zaterdag")))))) -> Dinsdag | B8: =B7+1 -> 46028 | J8: =IF(I8="","",IF(HOUR(I8)<5,0.5,1)) | K8: =IF(Basisgegevens!$F$1="JA",IF(D8="",0,(1-D8)+(E8)-G8),(E8-D8)-G8) -> 0 | L8: =IF(D8="","",ROUNDDOWN((HOUR(K8))+MINUTE(K8)/60,2)) | M8: =IF(C8="",0,(D8-C8)+(F8-E8)) -> 0 | N8: =IF(C8="","",ROUNDDOWN((HOUR(M8))+MINUTE(M8)/60,2)) | O8: =IF(OR(WEEKDAY(B8)=1,WEEKDAY(B8)=7,B8=Basisgegevens!B$4,B8=Basisgegevens!B$5,B8=Basisgegevens!B$6,B8=Basisgegevens!B$7,B8=Basisgegevens!B$8,B8=Basisgegevens!B$9,B8=Basisgegevens!B$10,B8=Basisgegevens!B$11,B8=Basisgegevens!B$12,B8=Basisgegevens!B$13,B8=Basisgegevens!B$14,B8=Basisgegevens!B$15),0,IF(K8<=(TIME(8,0,0)),K8,(TIME(8,0,0)))) -> 0 | P8: =IF(OR(WEEKDAY(B8)=1,B8=Basisgegevens!B$4,B8=Basisgegevens!B$5,B8=Basisgegevens!B$6,B8=Basisgegevens!B$7,B8=Basisgegevens!B$8,B8=Basisgegevens!B$9,B8=Basisgegevens!B$10,B8=Basisgegevens!B$11,B8=Basisgegevens!B$12,B8=Basisgegevens!B$13,B8=Basisgegevens!B$14,B8=Basisgegevens!B$15),0,IF(WEEKDAY(B8)=7,K8,K8-O8)) -> 0 | Q8: =IF(OR(WEEKDAY(B8)=1,B8=Basisgegevens!B$4,B8=Basisgegevens!B$5,B8=Basisgegevens!B$6,B8=Basisgegevens!B$7,B8=Basisgegevens!B$8,B8=Basisgegevens!B$9,B8=Basisgegevens!B$10,B8=Basisgegevens!B$11,B8=Basisgegevens!B$12,B8=Basisgegevens!B$13,B8=Basisgegevens!B$14,B8=Basisgegevens!B$15),K8,0) -> 0 | V8: =IF(OR(B8=Basisgegevens!$B$4,B8=Basisgegevens!$B$5,B8=Basisgegevens!$B$6,B8=Basisgegevens!$B$7,B8=Basisgegevens!$B$8,B8=Basisgegevens!$B$9,B8=Basisgegevens!$B$10,B8=Basisgegevens!$B$11,B8=Basisgegevens!$B$12,B8=Basisgegevens!$B$13,B8=Basisgegevens!$B$14,B8=Basisgegevens!$B$15),"FD","") | W8: =IF(WEEKDAY(B8)=1,(WEEKNUM(DATE(YEAR(B8),MONTH(B8),DAY(B8)),)-1),WEEKNUM(DATE(YEAR(B8),MONTH(B8),DAY(B8)),)) -> 2 | X8: =IF($D8="","",IF($B8<Basisgegevens!$H$4,((((DAY($O8))*24)+(HOUR($O8))+((MINUTE($O8))/60))*Basisgegevens!$I$3)+((((DAY($P8))*24)+(HOUR($P8))+((MINUTE($P8))/60))*Basisgegevens!$I$3*1.5)+((((DAY($Q8))*24)+(HOUR($Q8))+((MINUTE($Q8))/60))*Basisgegevens!$I$3*2)+Basisgegevens!$J$3,IF(Jan!$B8<Basisgegevens!$H$5,((((DAY($O8))*24)+(HOUR($O8))+((MINUTE($O8))/60))*Basisgegevens!$I$4)+((((DAY($P8))*24)+(HOUR($P8))+((MINUTE($P8))/60))*Basisgegevens!$I$4*1.5)+((((DAY($Q8))*24)+(HOUR($Q8))+((MINUTE($Q8))/60))*Basisgegevens!$I$4*2)+Basisgegevens!$J$4,((((DAY($O8))*24)+(HOUR($O8))+((MINUTE($O8))/60))*Basisgegevens!$I$5)+((((DAY($P8))*24)+(HOUR($P8))+((MINUTE($P8))/60))*Basisgegevens!$I$5*1.5)+((((DAY($Q8))*24)+(HOUR($Q8))+((MINUTE($Q8))/60))*Basisgegevens!$I$5*2)+Basisgegevens!$J$5))) | Y8: =IF($D8="","",IF($B8<Basisgegevens!$H$4,((((DAY($O8))*24)+(HOUR($O8))+((MINUTE($O8))/60))*Basisgegevens!$K$3)+((((DAY($P8))*24)+(HOUR($P8))+((MINUTE($P8))/60))*Basisgegevens!$K$3*1.5)+((((DAY($Q8))*24)+(HOUR($Q8))+((MINUTE($Q8))/60))*Basisgegevens!$K$3*2)+Basisgegevens!$L$3,IF(Jan!$B8<Basisgegevens!$H$5,((((DAY($O8))*24)+(HOUR($O8))+((MINUTE($O8))/60))*Basisgegevens!$K$4)+((((DAY($P8))*24)+(HOUR($P8))+((MINUTE($P8))/60))*Basisgegevens!$K$4*1.5)+((((DAY($Q8))*24)+(HOUR($Q8))+((MINUTE($Q8))/60))*Basisgegevens!$K$4*2)+Basisgegevens!$L$4,((((DAY($O8))*24)+(HOUR($O8))+((MINUTE($O8))/60))*Basisgegevens!$K$5)+((((DAY($P8))*24)+(HOUR($P8))+((MINUTE($P8))/60))*Basisgegevens!$K$5*1.5)+((((DAY($Q8))*24)+(HOUR($Q8))+((MINUTE($Q8))/60))*Basisgegevens!$K$5*2)+Basisgegevens!$L$5))) | Z8: =IF(W$33=Z7,"",Z7+1) -> 5 | AA8: =IF($Z8="","",SUMIFS($K$3:$K$33,$W$3:$W$33,$Z8,$A$3:$A$33,"<>Zaterdag",$A$3:$A$33,"<>Zondag")) -> 0 | AB8: =IF($Z8="","",SUMIFS($K$3:$K$33,$W$3:$W$33,$Z8,$A$3:$A$33,"<>Zaterdag",$A$3:$A$33,"<>Zondag")+SUMIFS($I$3:$I$33,$W$3:$W$33,$Z8,$A$3:$A$33,"<>Zaterdag",$A$3:$A$33,"<>Zondag")) -> 0 | AC8: =IF($Z8="","",SUMIFS($M$3:$M$33,$W$3:$W$33,$Z8,$A$3:$A$33,"<>Zaterdag",$A$3:$A$33,"<>Zondag")) -> 0 | AD8: =IF($Z8="","",SUMIFS($K$3:$K$33,$W$3:$W$33,$Z8,$A$3:$A$33,"<>Zaterdag",$A$3:$A$33,"<>Zondag")+SUMIFS($I$3:$I$33,$W$3:$W$33,$Z8,$A$3:$A$33,"<>Zaterdag",$A$3:$A$33,"<>Zondag",$H$3:$H$33,"=ADV")+SUMIFS($I$3:$I$33,$W$3:$W$33,$Z8,$A$3:$A$33,"<>Zaterdag",$A$3:$A$33,"<>Zondag",$H$3:$H$33,"=BF")+SUMIFS($I$3:$I$33,$W$3:$W$33,$Z8,$A$3:$A$33,"<>Zaterdag",$A$3:$A$33,"<>Zondag",$H$3:$H$33,"=BIR")+SUMIFS($I$3:$I$33,$W$3:$W$33,$Z8,$A$3:$A$33,"<>Zaterdag",$A$3:$A$33,"<>Zondag",$H$3:$H$33,"=OPL")) -> 0 | AE8: =IF(L8="",0,IF(L8>=5,1,0)) -> 0
A9: =IF(WEEKDAY(B9)=1,"Zondag",IF(WEEKDAY(B9)=2,"Maandag",IF(WEEKDAY(B9)=3,"Dinsdag",IF(WEEKDAY(B9)=4,"Woensdag",IF(WEEKDAY(B9)=5,"Donderdag",IF(WEEKDAY(B9)=6,"Vrijdag","Zaterdag")))))) -> Woensdag | B9: =B8+1 -> 46029 | J9: =IF(I9="","",IF(HOUR(I9)<5,0.5,1)) | K9: =IF(Basisgegevens!$F$1="JA",IF(D9="",0,(1-D9)+(E9)-G9),(E9-D9)-G9) -> 0 | L9: =IF(D9="","",ROUNDDOWN((HOUR(K9))+MINUTE(K9)/60,2)) | M9: =IF(C9="",0,(D9-C9)+(F9-E9)) -> 0 | N9: =IF(C9="","",ROUNDDOWN((HOUR(M9))+MINUTE(M9)/60,2)) | O9: =IF(OR(WEEKDAY(B9)=1,WEEKDAY(B9)=7,B9=Basisgegevens!B$4,B9=Basisgegevens!B$5,B9=Basisgegevens!B$6,B9=Basisgegevens!B$7,B9=Basisgegevens!B$8,B9=Basisgegevens!B$9,B9=Basisgegevens!B$10,B9=Basisgegevens!B$11,B9=Basisgegevens!B$12,B9=Basisgegevens!B$13,B9=Basisgegevens!B$14,B9=Basisgegevens!B$15),0,IF(K9<=(TIME(8,0,0)),K9,(TIME(8,0,0)))) -> 0 | P9: =IF(OR(WEEKDAY(B9)=1,B9=Basisgegevens!B$4,B9=Basisgegevens!B$5,B9=Basisgegevens!B$6,B9=Basisgegevens!B$7,B9=Basisgegevens!B$8,B9=Basisgegevens!B$9,B9=Basisgegevens!B$10,B9=Basisgegevens!B$11,B9=Basisgegevens!B$12,B9=Basisgegevens!B$13,B9=Basisgegevens!B$14,B9=Basisgegevens!B$15),0,IF(WEEKDAY(B9)=7,K9,K9-O9)) -> 0 | Q9: =IF(OR(WEEKDAY(B9)=1,B9=Basisgegevens!B$4,B9=Basisgegevens!B$5,B9=Basisgegevens!B$6,B9=Basisgegevens!B$7,B9=Basisgegevens!B$8,B9=Basisgegevens!B$9,B9=Basisgegevens!B$10,B9=Basisgegevens!B$11,B9=Basisgegevens!B$12,B9=Basisgegevens!B$13,B9=Basisgegevens!B$14,B9=Basisgegevens!B$15),K9,0) -> 0 | V9: =IF(OR(B9=Basisgegevens!$B$4,B9=Basisgegevens!$B$5,B9=Basisgegevens!$B$6,B9=Basisgegevens!$B$7,B9=Basisgegevens!$B$8,B9=Basisgegevens!$B$9,B9=Basisgegevens!$B$10,B9=Basisgegevens!$B$11,B9=Basisgegevens!$B$12,B9=Basisgegevens!$B$13,B9=Basisgegevens!$B$14,B9=Basisgegevens!$B$15),"FD","") | W9: =IF(WEEKDAY(B9)=1,(WEEKNUM(DATE(YEAR(B9),MONTH(B9),DAY(B9)),)-1),WEEKNUM(DATE(YEAR(B9),MONTH(B9),DAY(B9)),)) -> 2 | X9: =IF($D9="","",IF($B9<Basisgegevens!$H$4,((((DAY($O9))*24)+(HOUR($O9))+((MINUTE($O9))/60))*Basisgegevens!$I$3)+((((DAY($P9))*24)+(HOUR($P9))+((MINUTE($P9))/60))*Basisgegevens!$I$3*1.5)+((((DAY($Q9))*24)+(HOUR($Q9))+((MINUTE($Q9))/60))*Basisgegevens!$I$3*2)+Basisgegevens!$J$3,IF(Jan!$B9<Basisgegevens!$H$5,((((DAY($O9))*24)+(HOUR($O9))+((MINUTE($O9))/60))*Basisgegevens!$I$4)+((((DAY($P9))*24)+(HOUR($P9))+((MINUTE($P9))/60))*Basisgegevens!$I$4*1.5)+((((DAY($Q9))*24)+(HOUR($Q9))+((MINUTE($Q9))/60))*Basisgegevens!$I$4*2)+Basisgegevens!$J$4,((((DAY($O9))*24)+(HOUR($O9))+((MINUTE($O9))/60))*Basisgegevens!$I$5)+((((DAY($P9))*24)+(HOUR($P9))+((MINUTE($P9))/60))*Basisgegevens!$I$5*1.5)+((((DAY($Q9))*24)+(HOUR($Q9))+((MINUTE($Q9))/60))*Basisgegevens!$I$5*2)+Basisgegevens!$J$5))) | Y9: =IF($D9="","",IF($B9<Basisgegevens!$H$4,((((DAY($O9))*24)+(HOUR($O9))+((MINUTE($O9))/60))*Basisgegevens!$K$3)+((((DAY($P9))*24)+(HOUR($P9))+((MINUTE($P9))/60))*Basisgegevens!$K$3*1.5)+((((DAY($Q9))*24)+(HOUR($Q9))+((MINUTE($Q9))/60))*Basisgegevens!$K$3*2)+Basisgegevens!$L$3,IF(Jan!$B9<Basisgegevens!$H$5,((((DAY($O9))*24)+(HOUR($O9))+((MINUTE($O9))/60))*Basisgegevens!$K$4)+((((DAY($P9))*24)+(HOUR($P9))+((MINUTE($P9))/60))*Basisgegevens!$K$4*1.5)+((((DAY($Q9))*24)+(HOUR($Q9))+((MINUTE($Q9))/60))*Basisgegevens!$K$4*2)+Basisgegevens!$L$4,((((DAY($O9))*24)+(HOUR($O9))+((MINUTE($O9))/60))*Basisgegevens!$K$5)+((((DAY($P9))*24)+(HOUR($P9))+((MINUTE($P9))/60))*Basisgegevens!$K$5*1.5)+((((DAY($Q9))*24)+(HOUR($Q9))+((MINUTE($Q9))/60))*Basisgegevens!$K$5*2)+Basisgegevens!$L$5))) | Z9: =IF(W$33=Z8,"",Z8+1) | AA9: =IF($Z9="","",SUMIFS($K$3:$K$33,$W$3:$W$33,$Z9,$A$3:$A$33,"<>Zaterdag",$A$3:$A$33,"<>Zondag")) | AB9: =IF($Z9="","",SUMIFS($K$3:$K$33,$W$3:$W$33,$Z9,$A$3:$A$33,"<>Zaterdag",$A$3:$A$33,"<>Zondag")+SUMIFS($I$3:$I$33,$W$3:$W$33,$Z9,$A$3:$A$33,"<>Zaterdag",$A$3:$A$33,"<>Zondag")) | AC9: =IF($Z9="","",SUMIFS($M$3:$M$33,$W$3:$W$33,$Z9,$A$3:$A$33,"<>Zaterdag",$A$3:$A$33,"<>Zondag")) | AD9: =IF($Z9="","",SUMIFS($K$3:$K$33,$W$3:$W$33,$Z9,$A$3:$A$33,"<>Zaterdag",$A$3:$A$33,"<>Zondag")+SUMIFS($I$3:$I$33,$W$3:$W$33,$Z9,$A$3:$A$33,"<>Zaterdag",$A$3:$A$33,"<>Zondag",$H$3:$H$33,"=ADV")+SUMIFS($I$3:$I$33,$W$3:$W$33,$Z9,$A$3:$A$33,"<>Zaterdag",$A$3:$A$33,"<>Zondag",$H$3:$H$33,"=BF")+SUMIFS($I$3:$I$33,$W$3:$W$33,$Z9,$A$3:$A$33,"<>Zaterdag",$A$3:$A$33,"<>Zondag",$H$3:$H$33,"=BIR")+SUMIFS($I$3:$I$33,$W$3:$W$33,$Z9,$A$3:$A$33,"<>Zaterdag",$A$3:$A$33,"<>Zondag",$H$3:$H$33,"=OPL")) | AE9: =IF(L9="",0,IF(L9>=5,1,0)) -> 0
A10: =IF(WEEKDAY(B10)=1,"Zondag",IF(WEEKDAY(B10)=2,"Maandag",IF(WEEKDAY(B10)=3,"Dinsdag",IF(WEEKDAY(B10)=4,"Woensdag",IF(WEEKDAY(B10)=5,"Donderdag",IF(WEEKDAY(B10)=6,"Vrijdag","Zaterdag")))))) -> Donderdag | B10: =B9+1 -> 46030 | J10: =IF(I10="","",IF(HOUR(I10)<5,0.5,1)) | K10: =IF(Basisgegevens!$F$1="JA",IF(D10="",0,(1-D10)+(E10)-G10),(E10-D10)-G10) -> 0 | L10: =IF(D10="","",ROUNDDOWN((HOUR(K10))+MINUTE(K10)/60,2)) | M10: =IF(C10="",0,(D10-C10)+(F10-E10)) -> 0 | N10: =IF(C10="","",ROUNDDOWN((HOUR(M10))+MINUTE(M10)/60,2)) | O10: =IF(OR(WEEKDAY(B10)=1,WEEKDAY(B10)=7,B10=Basisgegevens!B$4,B10=Basisgegevens!B$5,B10=Basisgegevens!B$6,B10=Basisgegevens!B$7,B10=Basisgegevens!B$8,B10=Basisgegevens!B$9,B10=Basisgegevens!B$10,B10=Basisgegevens!B$11,B10=Basisgegevens!B$12,B10=Basisgegevens!B$13,B10=Basisgegevens!B$14,B10=Basisgegevens!B$15),0,IF(K10<=(TIME(8,0,0)),K10,(TIME(8,0,0)))) -> 0 | P10: =IF(OR(WEEKDAY(B10)=1,B10=Basisgegevens!B$4,B10=Basisgegevens!B$5,B10=Basisgegevens!B$6,B10=Basisgegevens!B$7,B10=Basisgegevens!B$8,B10=Basisgegevens!B$9,B10=Basisgegevens!B$10,B10=Basisgegevens!B$11,B10=Basisgegevens!B$12,B10=Basisgegevens!B$13,B10=Basisgegevens!B$14,B10=Basisgegevens!B$15),0,IF(WEEKDAY(B10)=7,K10,K10-O10)) -> 0 | Q10: =IF(OR(WEEKDAY(B10)=1,B10=Basisgegevens!B$4,B10=Basisgegevens!B$5,B10=Basisgegevens!B$6,B10=Basisgegevens!B$7,B10=Basisgegevens!B$8,B10=Basisgegevens!B$9,B10=Basisgegevens!B$10,B10=Basisgegevens!B$11,B10=Basisgegevens!B$12,B10=Basisgegevens!B$13,B10=Basisgegevens!B$14,B10=Basisgegevens!B$15),K10,0) -> 0 | V10: =IF(OR(B10=Basisgegevens!$B$4,B10=Basisgegevens!$B$5,B10=Basisgegevens!$B$6,B10=Basisgegevens!$B$7,B10=Basisgegevens!$B$8,B10=Basisgegevens!$B$9,B10=Basisgegevens!$B$10,B10=Basisgegevens!$B$11,B10=Basisgegevens!$B$12,B10=Basisgegevens!$B$13,B10=Basisgegevens!$B$14,B10=Basisgegevens!$B$15),"FD","") | W10: =IF(WEEKDAY(B10)=1,(WEEKNUM(DATE(YEAR(B10),MONTH(B10),DAY(B10)),)-1),WEEKNUM(DATE(YEAR(B10),MONTH(B10),DAY(B10)),)) -> 2 | X10: =IF($D10="","",IF($B10<Basisgegevens!$H$4,((((DAY($O10))*24)+(HOUR($O10))+((MINUTE($O10))/60))*Basisgegevens!$I$3)+((((DAY($P10))*24)+(HOUR($P10))+((MINUTE($P10))/60))*Basisgegevens!$I$3*1.5)+((((DAY($Q10))*24)+(HOUR($Q10))+((MINUTE($Q10))/60))*Basisgegevens!$I$3*2)+Basisgegevens!$J$3,IF(Jan!$B10<Basisgegevens!$H$5,((((DAY($O10))*24)+(HOUR($O10))+((MINUTE($O10))/60))*Basisgegevens!$I$4)+((((DAY($P10))*24)+(HOUR($P10))+((MINUTE($P10))/60))*Basisgegevens!$I$4*1.5)+((((DAY($Q10))*24)+(HOUR($Q10))+((MINUTE($Q10))/60))*Basisgegevens!$I$4*2)+Basisgegevens!$J$4,((((DAY($O10))*24)+(HOUR($O10))+((MINUTE($O10))/60))*Basisgegevens!$I$5)+((((DAY($P10))*24)+(HOUR($P10))+((MINUTE($P10))/60))*Basisgegevens!$I$5*1.5)+((((DAY($Q10))*24)+(HOUR($Q10))+((MINUTE($Q10))/60))*Basisgegevens!$I$5*2)+Basisgegevens!$J$5))) | Y10: =IF($D10="","",IF($B10<Basisgegevens!$H$4,((((DAY($O10))*24)+(HOUR($O10))+((MINUTE($O10))/60))*Basisgegevens!$K$3)+((((DAY($P10))*24)+(HOUR($P10))+((MINUTE($P10))/60))*Basisgegevens!$K$3*1.5)+((((DAY($Q10))*24)+(HOUR($Q10))+((MINUTE($Q10))/60))*Basisgegevens!$K$3*2)+Basisgegevens!$L$3,IF(Jan!$B10<Basisgegevens!$H$5,((((DAY($O10))*24)+(HOUR($O10))+((MINUTE($O10))/60))*Basisgegevens!$K$4)+((((DAY($P10))*24)+(HOUR($P10))+((MINUTE($P10))/60))*Basisgegevens!$K$4*1.5)+((((DAY($Q10))*24)+(HOUR($Q10))+((MINUTE($Q10))/60))*Basisgegevens!$K$4*2)+Basisgegevens!$L$4,((((DAY($O10))*24)+(HOUR($O10))+((MINUTE($O10))/60))*Basisgegevens!$K$5)+((((DAY($P10))*24)+(HOUR($P10))+((MINUTE($P10))/60))*Basisgegevens!$K$5*1.5)+((((DAY($Q10))*24)+(HOUR($Q10))+((MINUTE($Q10))/60))*Basisgegevens!$K$5*2)+Basisgegevens!$L$5))) | AE10: =IF(L10="",0,IF(L10>=5,1,0)) -> 0
A11: =IF(WEEKDAY(B11)=1,"Zondag",IF(WEEKDAY(B11)=2,"Maandag",IF(WEEKDAY(B11)=3,"Dinsdag",IF(WEEKDAY(B11)=4,"Woensdag",IF(WEEKDAY(B11)=5,"Donderdag",IF(WEEKDAY(B11)=6,"Vrijdag","Zaterdag")))))) -> Vrijdag | B11: =B10+1 -> 46031 | J11: =IF(I11="","",IF(HOUR(I11)<5,0.5,1)) | K11: =IF(Basisgegevens!$F$1="JA",IF(D11="",0,(1-D11)+(E11)-G11),(E11-D11)-G11) -> 0 | L11: =IF(D11="","",ROUNDDOWN((HOUR(K11))+MINUTE(K11)/60,2)) | M11: =IF(C11="",0,(D11-C11)+(F11-E11)) -> 0 | N11: =IF(C11="","",ROUNDDOWN((HOUR(M11))+MINUTE(M11)/60,2)) | O11: =IF(OR(WEEKDAY(B11)=1,WEEKDAY(B11)=7,B11=Basisgegevens!B$4,B11=Basisgegevens!B$5,B11=Basisgegevens!B$6,B11=Basisgegevens!B$7,B11=Basisgegevens!B$8,B11=Basisgegevens!B$9,B11=Basisgegevens!B$10,B11=Basisgegevens!B$11,B11=Basisgegevens!B$12,B11=Basisgegevens!B$13,B11=Basisgegevens!B$14,B11=Basisgegevens!B$15),0,IF(K11<=(TIME(8,0,0)),K11,(TIME(8,0,0)))) -> 0 | P11: =IF(OR(WEEKDAY(B11)=1,B11=Basisgegevens!B$4,B11=Basisgegevens!B$5,B11=Basisgegevens!B$6,B11=Basisgegevens!B$7,B11=Basisgegevens!B$8,B11=Basisgegevens!B$9,B11=Basisgegevens!B$10,B11=Basisgegevens!B$11,B11=Basisgegevens!B$12,B11=Basisgegevens!B$13,B11=Basisgegevens!B$14,B11=Basisgegevens!B$15),0,IF(WEEKDAY(B11)=7,K11,K11-O11)) -> 0 | Q11: =IF(OR(WEEKDAY(B11)=1,B11=Basisgegevens!B$4,B11=Basisgegevens!B$5,B11=Basisgegevens!B$6,B11=Basisgegevens!B$7,B11=Basisgegevens!B$8,B11=Basisgegevens!B$9,B11=Basisgegevens!B$10,B11=Basisgegevens!B$11,B11=Basisgegevens!B$12,B11=Basisgegevens!B$13,B11=Basisgegevens!B$14,B11=Basisgegevens!B$15),K11,0) -> 0 | V11: =IF(OR(B11=Basisgegevens!$B$4,B11=Basisgegevens!$B$5,B11=Basisgegevens!$B$6,B11=Basisgegevens!$B$7,B11=Basisgegevens!$B$8,B11=Basisgegevens!$B$9,B11=Basisgegevens!$B$10,B11=Basisgegevens!$B$11,B11=Basisgegevens!$B$12,B11=Basisgegevens!$B$13,B11=Basisgegevens!$B$14,B11=Basisgegevens!$B$15),"FD","") | W11: =IF(WEEKDAY(B11)=1,(WEEKNUM(DATE(YEAR(B11),MONTH(B11),DAY(B11)),)-1),WEEKNUM(DATE(YEAR(B11),MONTH(B11),DAY(B11)),)) -> 2 | X11: =IF($D11="","",IF($B11<Basisgegevens!$H$4,((((DAY($O11))*24)+(HOUR($O11))+((MINUTE($O11))/60))*Basisgegevens!$I$3)+((((DAY($P11))*24)+(HOUR($P11))+((MINUTE($P11))/60))*Basisgegevens!$I$3*1.5)+((((DAY($Q11))*24)+(HOUR($Q11))+((MINUTE($Q11))/60))*Basisgegevens!$I$3*2)+Basisgegevens!$J$3,IF(Jan!$B11<Basisgegevens!$H$5,((((DAY($O11))*24)+(HOUR($O11))+((MINUTE($O11))/60))*Basisgegevens!$I$4)+((((DAY($P11))*24)+(HOUR($P11))+((MINUTE($P11))/60))*Basisgegevens!$I$4*1.5)+((((DAY($Q11))*24)+(HOUR($Q11))+((MINUTE($Q11))/60))*Basisgegevens!$I$4*2)+Basisgegevens!$J$4,((((DAY($O11))*24)+(HOUR($O11))+((MINUTE($O11))/60))*Basisgegevens!$I$5)+((((DAY($P11))*24)+(HOUR($P11))+((MINUTE($P11))/60))*Basisgegevens!$I$5*1.5)+((((DAY($Q11))*24)+(HOUR($Q11))+((MINUTE($Q11))/60))*Basisgegevens!$I$5*2)+Basisgegevens!$J$5))) | Y11: =IF($D11="","",IF($B11<Basisgegevens!$H$4,((((DAY($O11))*24)+(HOUR($O11))+((MINUTE($O11))/60))*Basisgegevens!$K$3)+((((DAY($P11))*24)+(HOUR($P11))+((MINUTE($P11))/60))*Basisgegevens!$K$3*1.5)+((((DAY($Q11))*24)+(HOUR($Q11))+((MINUTE($Q11))/60))*Basisgegevens!$K$3*2)+Basisgegevens!$L$3,IF(Jan!$B11<Basisgegevens!$H$5,((((DAY($O11))*24)+(HOUR($O11))+((MINUTE($O11))/60))*Basisgegevens!$K$4)+((((DAY($P11))*24)+(HOUR($P11))+((MINUTE($P11))/60))*Basisgegevens!$K$4*1.5)+((((DAY($Q11))*24)+(HOUR($Q11))+((MINUTE($Q11))/60))*Basisgegevens!$K$4*2)+Basisgegevens!$L$4,((((DAY($O11))*24)+(HOUR($O11))+((MINUTE($O11))/60))*Basisgegevens!$K$5)+((((DAY($P11))*24)+(HOUR($P11))+((MINUTE($P11))/60))*Basisgegevens!$K$5*1.5)+((((DAY($Q11))*24)+(HOUR($Q11))+((MINUTE($Q11))/60))*Basisgegevens!$K$5*2)+Basisgegevens!$L$5))) | Z11: WEEK | AA11: Werkuren | AB11: Totale uren | AC11: Reisuren | AE11: =IF(L11="",0,IF(L11>=5,1,0)) -> 0
A12: =IF(WEEKDAY(B12)=1,"Zondag",IF(WEEKDAY(B12)=2,"Maandag",IF(WEEKDAY(B12)=3,"Dinsdag",IF(WEEKDAY(B12)=4,"Woensdag",IF(WEEKDAY(B12)=5,"Donderdag",IF(WEEKDAY(B12)=6,"Vrijdag","Zaterdag")))))) -> Zaterdag | B12: =B11+1 -> 46032 | J12: =IF(I12="","",IF(HOUR(I12)<5,0.5,1)) | K12: =IF(Basisgegevens!$F$1="JA",IF(D12="",0,(1-D12)+(E12)-G12),(E12-D12)-G12) -> 0 | L12: =IF(D12="","",ROUNDDOWN((HOUR(K12))+MINUTE(K12)/60,2)) | M12: =IF(C12="",0,(D12-C12)+(F12-E12)) -> 0 | N12: =IF(C12="","",ROUNDDOWN((HOUR(M12))+MINUTE(M12)/60,2)) | O12: =IF(OR(WEEKDAY(B12)=1,WEEKDAY(B12)=7,B12=Basisgegevens!B$4,B12=Basisgegevens!B$5,B12=Basisgegevens!B$6,B12=Basisgegevens!B$7,B12=Basisgegevens!B$8,B12=Basisgegevens!B$9,B12=Basisgegevens!B$10,B12=Basisgegevens!B$11,B12=Basisgegevens!B$12,B12=Basisgegevens!B$13,B12=Basisgegevens!B$14,B12=Basisgegevens!B$15),0,IF(K12<=(TIME(8,0,0)),K12,(TIME(8,0,0)))) -> 0 | P12: =IF(OR(WEEKDAY(B12)=1,B12=Basisgegevens!B$4,B12=Basisgegevens!B$5,B12=Basisgegevens!B$6,B12=Basisgegevens!B$7,B12=Basisgegevens!B$8,B12=Basisgegevens!B$9,B12=Basisgegevens!B$10,B12=Basisgegevens!B$11,B12=Basisgegevens!B$12,B12=Basisgegevens!B$13,B12=Basisgegevens!B$14,B12=Basisgegevens!B$15),0,IF(WEEKDAY(B12)=7,K12,K12-O12)) -> 0 | Q12: =IF(OR(WEEKDAY(B12)=1,B12=Basisgegevens!B$4,B12=Basisgegevens!B$5,B12=Basisgegevens!B$6,B12=Basisgegevens!B$7,B12=Basisgegevens!B$8,B12=Basisgegevens!B$9,B12=Basisgegevens!B$10,B12=Basisgegevens!B$11,B12=Basisgegevens!B$12,B12=Basisgegevens!B$13,B12=Basisgegevens!B$14,B12=Basisgegevens!B$15),K12,0) -> 0 | V12: =IF(OR(B12=Basisgegevens!$B$4,B12=Basisgegevens!$B$5,B12=Basisgegevens!$B$6,B12=Basisgegevens!$B$7,B12=Basisgegevens!$B$8,B12=Basisgegevens!$B$9,B12=Basisgegevens!$B$10,B12=Basisgegevens!$B$11,B12=Basisgegevens!$B$12,B12=Basisgegevens!$B$13,B12=Basisgegevens!$B$14,B12=Basisgegevens!$B$15),"FD","") | W12: =IF(WEEKDAY(B12)=1,(WEEKNUM(DATE(YEAR(B12),MONTH(B12),DAY(B12)),)-1),WEEKNUM(DATE(YEAR(B12),MONTH(B12),DAY(B12)),)) -> 2 | X12: =IF($D12="","",IF($B12<Basisgegevens!$H$4,((((DAY($O12))*24)+(HOUR($O12))+((MINUTE($O12))/60))*Basisgegevens!$I$3)+((((DAY($P12))*24)+(HOUR($P12))+((MINUTE($P12))/60))*Basisgegevens!$I$3*1.5)+((((DAY($Q12))*24)+(HOUR($Q12))+((MINUTE($Q12))/60))*Basisgegevens!$I$3*2)+Basisgegevens!$J$3,IF(Jan!$B12<Basisgegevens!$H$5,((((DAY($O12))*24)+(HOUR($O12))+((MINUTE($O12))/60))*Basisgegevens!$I$4)+((((DAY($P12))*24)+(HOUR($P12))+((MINUTE($P12))/60))*Basisgegevens!$I$4*1.5)+((((DAY($Q12))*24)+(HOUR($Q12))+((MINUTE($Q12))/60))*Basisgegevens!$I$4*2)+Basisgegevens!$J$4,((((DAY($O12))*24)+(HOUR($O12))+((MINUTE($O12))/60))*Basisgegevens!$I$5)+((((DAY($P12))*24)+(HOUR($P12))+((MINUTE($P12))/60))*Basisgegevens!$I$5*1.5)+((((DAY($Q12))*24)+(HOUR($Q12))+((MINUTE($Q12))/60))*Basisgegevens!$I$5*2)+Basisgegevens!$J$5))) | Y12: =IF($D12="","",IF($B12<Basisgegevens!$H$4,((((DAY($O12))*24)+(HOUR($O12))+((MINUTE($O12))/60))*Basisgegevens!$K$3)+((((DAY($P12))*24)+(HOUR($P12))+((MINUTE($P12))/60))*Basisgegevens!$K$3*1.5)+((((DAY($Q12))*24)+(HOUR($Q12))+((MINUTE($Q12))/60))*Basisgegevens!$K$3*2)+Basisgegevens!$L$3,IF(Jan!$B12<Basisgegevens!$H$5,((((DAY($O12))*24)+(HOUR($O12))+((MINUTE($O12))/60))*Basisgegevens!$K$4)+((((DAY($P12))*24)+(HOUR($P12))+((MINUTE($P12))/60))*Basisgegevens!$K$4*1.5)+((((DAY($Q12))*24)+(HOUR($Q12))+((MINUTE($Q12))/60))*Basisgegevens!$K$4*2)+Basisgegevens!$L$4,((((DAY($O12))*24)+(HOUR($O12))+((MINUTE($O12))/60))*Basisgegevens!$K$5)+((((DAY($P12))*24)+(HOUR($P12))+((MINUTE($P12))/60))*Basisgegevens!$K$5*1.5)+((((DAY($Q12))*24)+(HOUR($Q12))+((MINUTE($Q12))/60))*Basisgegevens!$K$5*2)+Basisgegevens!$L$5))) | Z12: =Z4 -> 1 | AA12: =IF(AA4="","",AA4*24) -> 0 | AB12: =IF(AB4="","",AB4*24) -> 0 | AC12: =IF(AC4="","",AC4*24) -> 0 | AE12: =IF(L12="",0,IF(L12>=5,1,0)) -> 0
A13: =IF(WEEKDAY(B13)=1,"Zondag",IF(WEEKDAY(B13)=2,"Maandag",IF(WEEKDAY(B13)=3,"Dinsdag",IF(WEEKDAY(B13)=4,"Woensdag",IF(WEEKDAY(B13)=5,"Donderdag",IF(WEEKDAY(B13)=6,"Vrijdag","Zaterdag")))))) -> Zondag | B13: =B12+1 -> 46033 | J13: =IF(I13="","",IF(HOUR(I13)<5,0.5,1)) | K13: =IF(Basisgegevens!$F$1="JA",IF(D13="",0,(1-D13)+(E13)-G13),(E13-D13)-G13) -> 0 | L13: =IF(D13="","",ROUNDDOWN((HOUR(K13))+MINUTE(K13)/60,2)) | M13: =IF(C13="",0,(D13-C13)+(F13-E13)) -> 0 | N13: =IF(C13="","",ROUNDDOWN((HOUR(M13))+MINUTE(M13)/60,2)) | O13: =IF(OR(WEEKDAY(B13)=1,WEEKDAY(B13)=7,B13=Basisgegevens!B$4,B13=Basisgegevens!B$5,B13=Basisgegevens!B$6,B13=Basisgegevens!B$7,B13=Basisgegevens!B$8,B13=Basisgegevens!B$9,B13=Basisgegevens!B$10,B13=Basisgegevens!B$11,B13=Basisgegevens!B$12,B13=Basisgegevens!B$13,B13=Basisgegevens!B$14,B13=Basisgegevens!B$15),0,IF(K13<=(TIME(8,0,0)),K13,(TIME(8,0,0)))) -> 0 | P13: =IF(OR(WEEKDAY(B13)=1,B13=Basisgegevens!B$4,B13=Basisgegevens!B$5,B13=Basisgegevens!B$6,B13=Basisgegevens!B$7,B13=Basisgegevens!B$8,B13=Basisgegevens!B$9,B13=Basisgegevens!B$10,B13=Basisgegevens!B$11,B13=Basisgegevens!B$12,B13=Basisgegevens!B$13,B13=Basisgegevens!B$14,B13=Basisgegevens!B$15),0,IF(WEEKDAY(B13)=7,K13,K13-O13)) -> 0 | Q13: =IF(OR(WEEKDAY(B13)=1,B13=Basisgegevens!B$4,B13=Basisgegevens!B$5,B13=Basisgegevens!B$6,B13=Basisgegevens!B$7,B13=Basisgegevens!B$8,B13=Basisgegevens!B$9,B13=Basisgegevens!B$10,B13=Basisgegevens!B$11,B13=Basisgegevens!B$12,B13=Basisgegevens!B$13,B13=Basisgegevens!B$14,B13=Basisgegevens!B$15),K13,0) -> 0 | V13: =IF(OR(B13=Basisgegevens!$B$4,B13=Basisgegevens!$B$5,B13=Basisgegevens!$B$6,B13=Basisgegevens!$B$7,B13=Basisgegevens!$B$8,B13=Basisgegevens!$B$9,B13=Basisgegevens!$B$10,B13=Basisgegevens!$B$11,B13=Basisgegevens!$B$12,B13=Basisgegevens!$B$13,B13=Basisgegevens!$B$14,B13=Basisgegevens!$B$15),"FD","") | W13: =IF(WEEKDAY(B13)=1,(WEEKNUM(DATE(YEAR(B13),MONTH(B13),DAY(B13)),)-1),WEEKNUM(DATE(YEAR(B13),MONTH(B13),DAY(B13)),)) -> 2 | X13: =IF($D13="","",IF($B13<Basisgegevens!$H$4,((((DAY($O13))*24)+(HOUR($O13))+((MINUTE($O13))/60))*Basisgegevens!$I$3)+((((DAY($P13))*24)+(HOUR($P13))+((MINUTE($P13))/60))*Basisgegevens!$I$3*1.5)+((((DAY($Q13))*24)+(HOUR($Q13))+((MINUTE($Q13))/60))*Basisgegevens!$I$3*2)+Basisgegevens!$J$3,IF(Jan!$B13<Basisgegevens!$H$5,((((DAY($O13))*24)+(HOUR($O13))+((MINUTE($O13))/60))*Basisgegevens!$I$4)+((((DAY($P13))*24)+(HOUR($P13))+((MINUTE($P13))/60))*Basisgegevens!$I$4*1.5)+((((DAY($Q13))*24)+(HOUR($Q13))+((MINUTE($Q13))/60))*Basisgegevens!$I$4*2)+Basisgegevens!$J$4,((((DAY($O13))*24)+(HOUR($O13))+((MINUTE($O13))/60))*Basisgegevens!$I$5)+((((DAY($P13))*24)+(HOUR($P13))+((MINUTE($P13))/60))*Basisgegevens!$I$5*1.5)+((((DAY($Q13))*24)+(HOUR($Q13))+((MINUTE($Q13))/60))*Basisgegevens!$I$5*2)+Basisgegevens!$J$5))) | Y13: =IF($D13="","",IF($B13<Basisgegevens!$H$4,((((DAY($O13))*24)+(HOUR($O13))+((MINUTE($O13))/60))*Basisgegevens!$K$3)+((((DAY($P13))*24)+(HOUR($P13))+((MINUTE($P13))/60))*Basisgegevens!$K$3*1.5)+((((DAY($Q13))*24)+(HOUR($Q13))+((MINUTE($Q13))/60))*Basisgegevens!$K$3*2)+Basisgegevens!$L$3,IF(Jan!$B13<Basisgegevens!$H$5,((((DAY($O13))*24)+(HOUR($O13))+((MINUTE($O13))/60))*Basisgegevens!$K$4)+((((DAY($P13))*24)+(HOUR($P13))+((MINUTE($P13))/60))*Basisgegevens!$K$4*1.5)+((((DAY($Q13))*24)+(HOUR($Q13))+((MINUTE($Q13))/60))*Basisgegevens!$K$4*2)+Basisgegevens!$L$4,((((DAY($O13))*24)+(HOUR($O13))+((MINUTE($O13))/60))*Basisgegevens!$K$5)+((((DAY($P13))*24)+(HOUR($P13))+((MINUTE($P13))/60))*Basisgegevens!$K$5*1.5)+((((DAY($Q13))*24)+(HOUR($Q13))+((MINUTE($Q13))/60))*Basisgegevens!$K$5*2)+Basisgegevens!$L$5))) | Z13: =Z5 -> 2 | AA13: =IF(AA5="","",AA5*24) -> 0 | AB13: =IF(AB5="","",AB5*24) -> 0 | AC13: =IF(AC5="","",AC5*24) -> 0 | AE13: =IF(L13="",0,IF(L13>=5,1,0)) -> 0
A14: =IF(WEEKDAY(B14)=1,"Zondag",IF(WEEKDAY(B14)=2,"Maandag",IF(WEEKDAY(B14)=3,"Dinsdag",IF(WEEKDAY(B14)=4,"Woensdag",IF(WEEKDAY(B14)=5,"Donderdag",IF(WEEKDAY(B14)=6,"Vrijdag","Zaterdag")))))) -> Maandag | B14: =B13+1 -> 46034 | J14: =IF(I14="","",IF(HOUR(I14)<5,0.5,1)) | K14: =IF(Basisgegevens!$F$1="JA",IF(D14="",0,(1-D14)+(E14)-G14),(E14-D14)-G14) -> 0 | L14: =IF(D14="","",ROUNDDOWN((HOUR(K14))+MINUTE(K14)/60,2)) | M14: =IF(C14="",0,(D14-C14)+(F14-E14)) -> 0 | N14: =IF(C14="","",ROUNDDOWN((HOUR(M14))+MINUTE(M14)/60,2)) | O14: =IF(OR(WEEKDAY(B14)=1,WEEKDAY(B14)=7,B14=Basisgegevens!B$4,B14=Basisgegevens!B$5,B14=Basisgegevens!B$6,B14=Basisgegevens!B$7,B14=Basisgegevens!B$8,B14=Basisgegevens!B$9,B14=Basisgegevens!B$10,B14=Basisgegevens!B$11,B14=Basisgegevens!B$12,B14=Basisgegevens!B$13,B14=Basisgegevens!B$14,B14=Basisgegevens!B$15),0,IF(K14<=(TIME(8,0,0)),K14,(TIME(8,0,0)))) -> 0 | P14: =IF(OR(WEEKDAY(B14)=1,B14=Basisgegevens!B$4,B14=Basisgegevens!B$5,B14=Basisgegevens!B$6,B14=Basisgegevens!B$7,B14=Basisgegevens!B$8,B14=Basisgegevens!B$9,B14=Basisgegevens!B$10,B14=Basisgegevens!B$11,B14=Basisgegevens!B$12,B14=Basisgegevens!B$13,B14=Basisgegevens!B$14,B14=Basisgegevens!B$15),0,IF(WEEKDAY(B14)=7,K14,K14-O14)) -> 0 | Q14: =IF(OR(WEEKDAY(B14)=1,B14=Basisgegevens!B$4,B14=Basisgegevens!B$5,B14=Basisgegevens!B$6,B14=Basisgegevens!B$7,B14=Basisgegevens!B$8,B14=Basisgegevens!B$9,B14=Basisgegevens!B$10,B14=Basisgegevens!B$11,B14=Basisgegevens!B$12,B14=Basisgegevens!B$13,B14=Basisgegevens!B$14,B14=Basisgegevens!B$15),K14,0) -> 0 | V14: =IF(OR(B14=Basisgegevens!$B$4,B14=Basisgegevens!$B$5,B14=Basisgegevens!$B$6,B14=Basisgegevens!$B$7,B14=Basisgegevens!$B$8,B14=Basisgegevens!$B$9,B14=Basisgegevens!$B$10,B14=Basisgegevens!$B$11,B14=Basisgegevens!$B$12,B14=Basisgegevens!$B$13,B14=Basisgegevens!$B$14,B14=Basisgegevens!$B$15),"FD","") | W14: =IF(WEEKDAY(B14)=1,(WEEKNUM(DATE(YEAR(B14),MONTH(B14),DAY(B14)),)-1),WEEKNUM(DATE(YEAR(B14),MONTH(B14),DAY(B14)),)) -> 3 | X14: =IF($D14="","",IF($B14<Basisgegevens!$H$4,((((DAY($O14))*24)+(HOUR($O14))+((MINUTE($O14))/60))*Basisgegevens!$I$3)+((((DAY($P14))*24)+(HOUR($P14))+((MINUTE($P14))/60))*Basisgegevens!$I$3*1.5)+((((DAY($Q14))*24)+(HOUR($Q14))+((MINUTE($Q14))/60))*Basisgegevens!$I$3*2)+Basisgegevens!$J$3,IF(Jan!$B14<Basisgegevens!$H$5,((((DAY($O14))*24)+(HOUR($O14))+((MINUTE($O14))/60))*Basisgegevens!$I$4)+((((DAY($P14))*24)+(HOUR($P14))+((MINUTE($P14))/60))*Basisgegevens!$I$4*1.5)+((((DAY($Q14))*24)+(HOUR($Q14))+((MINUTE($Q14))/60))*Basisgegevens!$I$4*2)+Basisgegevens!$J$4,((((DAY($O14))*24)+(HOUR($O14))+((MINUTE($O14))/60))*Basisgegevens!$I$5)+((((DAY($P14))*24)+(HOUR($P14))+((MINUTE($P14))/60))*Basisgegevens!$I$5*1.5)+((((DAY($Q14))*24)+(HOUR($Q14))+((MINUTE($Q14))/60))*Basisgegevens!$I$5*2)+Basisgegevens!$J$5))) | Y14: =IF($D14="","",IF($B14<Basisgegevens!$H$4,((((DAY($O14))*24)+(HOUR($O14))+((MINUTE($O14))/60))*Basisgegevens!$K$3)+((((DAY($P14))*24)+(HOUR($P14))+((MINUTE($P14))/60))*Basisgegevens!$K$3*1.5)+((((DAY($Q14))*24)+(HOUR($Q14))+((MINUTE($Q14))/60))*Basisgegevens!$K$3*2)+Basisgegevens!$L$3,IF(Jan!$B14<Basisgegevens!$H$5,((((DAY($O14))*24)+(HOUR($O14))+((MINUTE($O14))/60))*Basisgegevens!$K$4)+((((DAY($P14))*24)+(HOUR($P14))+((MINUTE($P14))/60))*Basisgegevens!$K$4*1.5)+((((DAY($Q14))*24)+(HOUR($Q14))+((MINUTE($Q14))/60))*Basisgegevens!$K$4*2)+Basisgegevens!$L$4,((((DAY($O14))*24)+(HOUR($O14))+((MINUTE($O14))/60))*Basisgegevens!$K$5)+((((DAY($P14))*24)+(HOUR($P14))+((MINUTE($P14))/60))*Basisgegevens!$K$5*1.5)+((((DAY($Q14))*24)+(HOUR($Q14))+((MINUTE($Q14))/60))*Basisgegevens!$K$5*2)+Basisgegevens!$L$5))) | Z14: =Z6 -> 3 | AA14: =IF(AA6="","",AA6*24) -> 0 | AB14: =IF(AB6="","",AB6*24) -> 0 | AC14: =IF(AC6="","",AC6*24) -> 0 | AE14: =IF(L14="",0,IF(L14>=5,1,0)) -> 0
A15: =IF(WEEKDAY(B15)=1,"Zondag",IF(WEEKDAY(B15)=2,"Maandag",IF(WEEKDAY(B15)=3,"Dinsdag",IF(WEEKDAY(B15)=4,"Woensdag",IF(WEEKDAY(B15)=5,"Donderdag",IF(WEEKDAY(B15)=6,"Vrijdag","Zaterdag")))))) -> Dinsdag | B15: =B14+1 -> 46035 | J15: =IF(I15="","",IF(HOUR(I15)<5,0.5,1)) | K15: =IF(Basisgegevens!$F$1="JA",IF(D15="",0,(1-D15)+(E15)-G15),(E15-D15)-G15) -> 0 | L15: =IF(D15="","",ROUNDDOWN((HOUR(K15))+MINUTE(K15)/60,2)) | M15: =IF(C15="",0,(D15-C15)+(F15-E15)) -> 0 | N15: =IF(C15="","",ROUNDDOWN((HOUR(M15))+MINUTE(M15)/60,2)) | O15: =IF(OR(WEEKDAY(B15)=1,WEEKDAY(B15)=7,B15=Basisgegevens!B$4,B15=Basisgegevens!B$5,B15=Basisgegevens!B$6,B15=Basisgegevens!B$7,B15=Basisgegevens!B$8,B15=Basisgegevens!B$9,B15=Basisgegevens!B$10,B15=Basisgegevens!B$11,B15=Basisgegevens!B$12,B15=Basisgegevens!B$13,B15=Basisgegevens!B$14,B15=Basisgegevens!B$15),0,IF(K15<=(TIME(8,0,0)),K15,(TIME(8,0,0)))) -> 0 | P15: =IF(OR(WEEKDAY(B15)=1,B15=Basisgegevens!B$4,B15=Basisgegevens!B$5,B15=Basisgegevens!B$6,B15=Basisgegevens!B$7,B15=Basisgegevens!B$8,B15=Basisgegevens!B$9,B15=Basisgegevens!B$10,B15=Basisgegevens!B$11,B15=Basisgegevens!B$12,B15=Basisgegevens!B$13,B15=Basisgegevens!B$14,B15=Basisgegevens!B$15),0,IF(WEEKDAY(B15)=7,K15,K15-O15)) -> 0 | Q15: =IF(OR(WEEKDAY(B15)=1,B15=Basisgegevens!B$4,B15=Basisgegevens!B$5,B15=Basisgegevens!B$6,B15=Basisgegevens!B$7,B15=Basisgegevens!B$8,B15=Basisgegevens!B$9,B15=Basisgegevens!B$10,B15=Basisgegevens!B$11,B15=Basisgegevens!B$12,B15=Basisgegevens!B$13,B15=Basisgegevens!B$14,B15=Basisgegevens!B$15),K15,0) -> 0 | V15: =IF(OR(B15=Basisgegevens!$B$4,B15=Basisgegevens!$B$5,B15=Basisgegevens!$B$6,B15=Basisgegevens!$B$7,B15=Basisgegevens!$B$8,B15=Basisgegevens!$B$9,B15=Basisgegevens!$B$10,B15=Basisgegevens!$B$11,B15=Basisgegevens!$B$12,B15=Basisgegevens!$B$13,B15=Basisgegevens!$B$14,B15=Basisgegevens!$B$15),"FD","") | W15: =IF(WEEKDAY(B15)=1,(WEEKNUM(DATE(YEAR(B15),MONTH(B15),DAY(B15)),)-1),WEEKNUM(DATE(YEAR(B15),MONTH(B15),DAY(B15)),)) -> 3 | X15: =IF($D15="","",IF($B15<Basisgegevens!$H$4,((((DAY($O15))*24)+(HOUR($O15))+((MINUTE($O15))/60))*Basisgegevens!$I$3)+((((DAY($P15))*24)+(HOUR($P15))+((MINUTE($P15))/60))*Basisgegevens!$I$3*1.5)+((((DAY($Q15))*24)+(HOUR($Q15))+((MINUTE($Q15))/60))*Basisgegevens!$I$3*2)+Basisgegevens!$J$3,IF(Jan!$B15<Basisgegevens!$H$5,((((DAY($O15))*24)+(HOUR($O15))+((MINUTE($O15))/60))*Basisgegevens!$I$4)+((((DAY($P15))*24)+(HOUR($P15))+((MINUTE($P15))/60))*Basisgegevens!$I$4*1.5)+((((DAY($Q15))*24)+(HOUR($Q15))+((MINUTE($Q15))/60))*Basisgegevens!$I$4*2)+Basisgegevens!$J$4,((((DAY($O15))*24)+(HOUR($O15))+((MINUTE($O15))/60))*Basisgegevens!$I$5)+((((DAY($P15))*24)+(HOUR($P15))+((MINUTE($P15))/60))*Basisgegevens!$I$5*1.5)+((((DAY($Q15))*24)+(HOUR($Q15))+((MINUTE($Q15))/60))*Basisgegevens!$I$5*2)+Basisgegevens!$J$5))) | Y15: =IF($D15="","",IF($B15<Basisgegevens!$H$4,((((DAY($O15))*24)+(HOUR($O15))+((MINUTE($O15))/60))*Basisgegevens!$K$3)+((((DAY($P15))*24)+(HOUR($P15))+((MINUTE($P15))/60))*Basisgegevens!$K$3*1.5)+((((DAY($Q15))*24)+(HOUR($Q15))+((MINUTE($Q15))/60))*Basisgegevens!$K$3*2)+Basisgegevens!$L$3,IF(Jan!$B15<Basisgegevens!$H$5,((((DAY($O15))*24)+(HOUR($O15))+((MINUTE($O15))/60))*Basisgegevens!$K$4)+((((DAY($P15))*24)+(HOUR($P15))+((MINUTE($P15))/60))*Basisgegevens!$K$4*1.5)+((((DAY($Q15))*24)+(HOUR($Q15))+((MINUTE($Q15))/60))*Basisgegevens!$K$4*2)+Basisgegevens!$L$4,((((DAY($O15))*24)+(HOUR($O15))+((MINUTE($O15))/60))*Basisgegevens!$K$5)+((((DAY($P15))*24)+(HOUR($P15))+((MINUTE($P15))/60))*Basisgegevens!$K$5*1.5)+((((DAY($Q15))*24)+(HOUR($Q15))+((MINUTE($Q15))/60))*Basisgegevens!$K$5*2)+Basisgegevens!$L$5))) | Z15: =Z7 -> 4 | AA15: =IF(AA7="","",AA7*24) -> 0 | AB15: =IF(AB7="","",AB7*24) -> 0 | AC15: =IF(AC7="","",AC7*24) -> 0 | AE15: =IF(L15="",0,IF(L15>=5,1,0)) -> 0
A16: =IF(WEEKDAY(B16)=1,"Zondag",IF(WEEKDAY(B16)=2,"Maandag",IF(WEEKDAY(B16)=3,"Dinsdag",IF(WEEKDAY(B16)=4,"Woensdag",IF(WEEKDAY(B16)=5,"Donderdag",IF(WEEKDAY(B16)=6,"Vrijdag","Zaterdag")))))) -> Woensdag | B16: =B15+1 -> 46036 | J16: =IF(I16="","",IF(HOUR(I16)<5,0.5,1)) | K16: =IF(Basisgegevens!$F$1="JA",IF(D16="",0,(1-D16)+(E16)-G16),(E16-D16)-G16) -> 0 | L16: =IF(D16="","",ROUNDDOWN((HOUR(K16))+MINUTE(K16)/60,2)) | M16: =IF(C16="",0,(D16-C16)+(F16-E16)) -> 0 | N16: =IF(C16="","",ROUNDDOWN((HOUR(M16))+MINUTE(M16)/60,2)) | O16: =IF(OR(WEEKDAY(B16)=1,WEEKDAY(B16)=7,B16=Basisgegevens!B$4,B16=Basisgegevens!B$5,B16=Basisgegevens!B$6,B16=Basisgegevens!B$7,B16=Basisgegevens!B$8,B16=Basisgegevens!B$9,B16=Basisgegevens!B$10,B16=Basisgegevens!B$11,B16=Basisgegevens!B$12,B16=Basisgegevens!B$13,B16=Basisgegevens!B$14,B16=Basisgegevens!B$15),0,IF(K16<=(TIME(8,0,0)),K16,(TIME(8,0,0)))) -> 0 | P16: =IF(OR(WEEKDAY(B16)=1,B16=Basisgegevens!B$4,B16=Basisgegevens!B$5,B16=Basisgegevens!B$6,B16=Basisgegevens!B$7,B16=Basisgegevens!B$8,B16=Basisgegevens!B$9,B16=Basisgegevens!B$10,B16=Basisgegevens!B$11,B16=Basisgegevens!B$12,B16=Basisgegevens!B$13,B16=Basisgegevens!B$14,B16=Basisgegevens!B$15),0,IF(WEEKDAY(B16)=7,K16,K16-O16)) -> 0 | Q16: =IF(OR(WEEKDAY(B16)=1,B16=Basisgegevens!B$4,B16=Basisgegevens!B$5,B16=Basisgegevens!B$6,B16=Basisgegevens!B$7,B16=Basisgegevens!B$8,B16=Basisgegevens!B$9,B16=Basisgegevens!B$10,B16=Basisgegevens!B$11,B16=Basisgegevens!B$12,B16=Basisgegevens!B$13,B16=Basisgegevens!B$14,B16=Basisgegevens!B$15),K16,0) -> 0 | V16: =IF(OR(B16=Basisgegevens!$B$4,B16=Basisgegevens!$B$5,B16=Basisgegevens!$B$6,B16=Basisgegevens!$B$7,B16=Basisgegevens!$B$8,B16=Basisgegevens!$B$9,B16=Basisgegevens!$B$10,B16=Basisgegevens!$B$11,B16=Basisgegevens!$B$12,B16=Basisgegevens!$B$13,B16=Basisgegevens!$B$14,B16=Basisgegevens!$B$15),"FD","") | W16: =IF(WEEKDAY(B16)=1,(WEEKNUM(DATE(YEAR(B16),MONTH(B16),DAY(B16)),)-1),WEEKNUM(DATE(YEAR(B16),MONTH(B16),DAY(B16)),)) -> 3 | X16: =IF($D16="","",IF($B16<Basisgegevens!$H$4,((((DAY($O16))*24)+(HOUR($O16))+((MINUTE($O16))/60))*Basisgegevens!$I$3)+((((DAY($P16))*24)+(HOUR($P16))+((MINUTE($P16))/60))*Basisgegevens!$I$3*1.5)+((((DAY($Q16))*24)+(HOUR($Q16))+((MINUTE($Q16))/60))*Basisgegevens!$I$3*2)+Basisgegevens!$J$3,IF(Jan!$B16<Basisgegevens!$H$5,((((DAY($O16))*24)+(HOUR($O16))+((MINUTE($O16))/60))*Basisgegevens!$I$4)+((((DAY($P16))*24)+(HOUR($P16))+((MINUTE($P16))/60))*Basisgegevens!$I$4*1.5)+((((DAY($Q16))*24)+(HOUR($Q16))+((MINUTE($Q16))/60))*Basisgegevens!$I$4*2)+Basisgegevens!$J$4,((((DAY($O16))*24)+(HOUR($O16))+((MINUTE($O16))/60))*Basisgegevens!$I$5)+((((DAY($P16))*24)+(HOUR($P16))+((MINUTE($P16))/60))*Basisgegevens!$I$5*1.5)+((((DAY($Q16))*24)+(HOUR($Q16))+((MINUTE($Q16))/60))*Basisgegevens!$I$5*2)+Basisgegevens!$J$5))) | Y16: =IF($D16="","",IF($B16<Basisgegevens!$H$4,((((DAY($O16))*24)+(HOUR($O16))+((MINUTE($O16))/60))*Basisgegevens!$K$3)+((((DAY($P16))*24)+(HOUR($P16))+((MINUTE($P16))/60))*Basisgegevens!$K$3*1.5)+((((DAY($Q16))*24)+(HOUR($Q16))+((MINUTE($Q16))/60))*Basisgegevens!$K$3*2)+Basisgegevens!$L$3,IF(Jan!$B16<Basisgegevens!$H$5,((((DAY($O16))*24)+(HOUR($O16))+((MINUTE($O16))/60))*Basisgegevens!$K$4)+((((DAY($P16))*24)+(HOUR($P16))+((MINUTE($P16))/60))*Basisgegevens!$K$4*1.5)+((((DAY($Q16))*24)+(HOUR($Q16))+((MINUTE($Q16))/60))*Basisgegevens!$K$4*2)+Basisgegevens!$L$4,((((DAY($O16))*24)+(HOUR($O16))+((MINUTE($O16))/60))*Basisgegevens!$K$5)+((((DAY($P16))*24)+(HOUR($P16))+((MINUTE($P16))/60))*Basisgegevens!$K$5*1.5)+((((DAY($Q16))*24)+(HOUR($Q16))+((MINUTE($Q16))/60))*Basisgegevens!$K$5*2)+Basisgegevens!$L$5))) | Z16: =Z8 -> 5 | AA16: =IF(AA8="","",AA8*24) -> 0 | AB16: =IF(AB8="","",AB8*24) -> 0 | AC16: =IF(AC8="","",AC8*24) -> 0 | AE16: =IF(L16="",0,IF(L16>=5,1,0)) -> 0
